Workbook

Sheet 5kB
A1: Nedelja | B1: PO | C1: UT | D1: SR | E1: CE | F1: PE | G1: SU | H1: NE
A2: 1 | B2: XT | C2: zagrevanje 10min@ZA; 3x(1200m@10K +2min@ZA); hlađenje 5min@HL | D2: A | E2: zagrevanje 10min@ZA; 8x(200m@5K +1min@ZA); hlađenje 5min@HL | F2: E | G2: zagrevanje 10min@ZA; 1x20min@21K; hlađenje 5min@HL | H2: L
A3: 2 | B3: E | C3: zagrevanje 10min@ZA; 16x(100m@1.5K + 1min@ZA); hlađenje 5min@HL | D3: A | E3: zagrevanje 10min@ZA; 6x(800m@5K +30sec@ZA); hlađenje 5min@HL | F3: E | G3: zagrevanje 10min@ZA; 2x(1600m@5K+1min@ZA); hlađenje 5min@HL | H3: L1
A4: 3 | B4: XT | C4: zagrevanje 10min@ZA; 4x(1600m@10K +2min@ZA); hlađenje 5min@HL | D4: A | E4: zagrevanje 10min@ZA; 4x(200m@3K + 400m@5K + 4min@ZA) hlađenje 5min@HL | F4: E | G4: zagrevanje 10min@ZA; 1x25min@5K; hlađenje 5min@HL | H4: L
A5: 4 | B5: E | C5: zagrevanje 10min@ZA; 10x(100m@1.5K + 2min@ZA); hlađenje 5min@HL | D5: A | E5: zagrevanje 10min@ZA; 12x(400m@5K +15sec@ZA); hlađenje 5min@HL | F5: E | G5: zagrevanje 10min@ZA; 2x(600m@3K +1000m@5K + 4min@ZA) hlađenje 5min@HL | H5: L1
A6: 5 | B6: XT | C6: zagrevanje 10min@ZA; 3x(2km@10K +2min@ZA); hlađenje 5min@HL | D6: A | E6: zagrevanje 10min@ZA; 6x(200m@1.5K + 400@3K + 4min@ZA) hlađenje 5min@HL | F6: E | G6: zagrevanje 10min@ZA; 1x30min@5K; hlađenje 5min@HL | H6: L
A7: 6 | B7: E | C7: zagrevanje 10min@ZA; 8x(200m@1.5K + 1min@ZA); hlađenje 5min@HL | D7: A1 | E7: zagrevanje 10min@ZA; 3x(6min@10K +3min@ZA); hlađenje 5min@HL | F7: E | G7: zagrevanje 10min@ZA; 3x(1600m@5K +1min@ZA); hlađenje 5min@HL | H7: L1
A8: 7 | B8: XT | C8: zagrevanje 10min@ZA; 5x(1km@5K + 1min@ZA); hlađenje 5min@HL | D8: A | E8: zagrevanje 10min@ZA; 8x(200m@3K +1min@ZA); hlađenje 5min@HL | F8: E | G8: odmor | H8: zagrevanje 10min@ZA; 5k@5K; hlađenje 5min@HL
A9: 8 | B9: E | C9: zagrevanje 10min@ZA; 8x(100m@1.5K + 2min@ZA); hlađenje 5min@HL | D9: A | E9: zagrevanje 10min@ZA; 6x(800m@5K +30sec@ZA); hlađenje 5min@HL | F9: E | G9: zagrevanje 10min@ZA; 3x(600m@5K +1000m@10K+4min@ZA); hlađenje 5min@HL | H9: L1
A10: 9 | B10: XT | C10: zagrevanje 10min@ZA; 2x(2k@5K + 2min@ZA); hlađenje 5min@HL | D10: A | E10: zagrevanje 10min@ZA; 5x(3min@3K + 3min@ZA); hlađenje 5min@HL | F10: E | G10: zagrevanje 10min@ZA; 30min@10K; hlađenje 5min@HL | H10: L
A11: 10 | B11: E1 | C11: zagrevanje 10min@ZA; 10x(200m@1.5K + 2min@ZA); hlađenje 5min@HL | D11: A1 | E11: zagrevanje 10min@ZA; 5x(1k@5K + 1min@ZA); hlađenje 5min@HL | F11: E | G11: zagrevanje 10min@ZA; 4x(400m@3K +400m@5K + 3min@ZA) hlađenje 5min@HL | H11: L
A12: 11 | B12: E | C12: zagrevanje 10min@ZA; 6x(1k@10K + 1min@ZA); hlađenje 5min@HL | D12: A | E12: zagrevanje 10min@ZA; 5x(3min@3K + 3min@ZA); hlađenje 5min@HL | F12: E | G12: odmor | H12: zagrevanje 10min@ZA; 25min@5K; hlađenje 5min@HL
A13: 12 | B13: A | C13: zagrevanje 10min@ZA; 10min@5K; hlađenje 5min@HL | D13: XT | E13: zagrevanje 10min@ZA; 3x(1.5min@5K + 1.5min@ZA); hlađenje 5min@HL | F13: odmor | G13: 3k@ZA; 3x100m ubrzanja Ubrzanja se trče po ravnoj stazi i sa snagom od 85%. U pauzi se ili hoda ili lagano trči i ne počinje se ponovo dok se potpuno ne odmori. | H13: Obavezno uraditi zagrevanje laganim trčanjem na samom startu barem 500m do 1km Trka: 5km
A14: Nedelja | B14: PO | C14: UT | D14: SR | E14: CE | F14: PE | G14: SU | H14: NE
A15: 1 | B15: =VLOOKUP(B2,Legenda!$A$1:$B$51,2,FALSE) -> Plivanje, bicikla, šetanje, vežbe snage, ... | C15: =SUBSTITUTE(SUBSTITUTE(SUBSTITUTE(SUBSTITUTE(SUBSTITUTE(SUBSTITUTE(SUBSTITUTE(SUBSTITUTE(C2,"1.5K",VO2max!B2),"3K",VO2max!C2),"5K",VO2max!D2),"10K",VO2max!E2),"21k",VO2max!F2),"42K",VO2max!G2),"ZA",VO2max!H2),"HL",VO2max!I2) -> zagrevanje 10min@7:30; 3x(1200m@6:20 +2min@7:30); hlađenje 5min@7:30 | D15: =VLOOKUP(D2,Legenda!$A$1:$B$51,2,FALSE) -> 5k@6:00 ili odmor | E15: =SUBSTITUTE(SUBSTITUTE(SUBSTITUTE(SUBSTITUTE(SUBSTITUTE(SUBSTITUTE(SUBSTITUTE(SUBSTITUTE(E2,"1.5K",VO2max!B2),"3K",VO2max!C2),"5K",VO2max!D2),"10K",VO2max!E2),"21k",VO2max!F2),"42K",VO2max!G2),"ZA",VO2max!H2),"HL",VO2max!I2) -> zagrevanje 10min@7:30; 8x(200m@6:05 +1min@7:30); hlađenje 5min@7:30 | F15: =VLOOKUP(F2,Legenda!$A$1:$B$51,2,FALSE) -> 5k@6:00 ili odmor | G15: =SUBSTITUTE(SUBSTITUTE(SUBSTITUTE(SUBSTITUTE(SUBSTITUTE(SUBSTITUTE(SUBSTITUTE(SUBSTITUTE(G2,"1.5K",VO2max!B2),"3K",VO2max!C2),"5K",VO2max!D2),"10K",VO2max!E2),"21K",VO2max!F2),"42K",VO2max!G2),"ZA",VO2max!H2),"HL",VO2max!I2) -> zagrevanje 10min@7:30; 1x20min@6:40; hlađenje 5min@7:30 | H15: =VLOOKUP(H2,Legenda!$A$1:$B$51,2,FALSE) -> 14k@6:00
A16: 2 | B16: =VLOOKUP(B3,Legenda!$A$1:$B$51,2,FALSE) -> 5k@6:00 ili odmor | C16: =SUBSTITUTE(SUBSTITUTE(SUBSTITUTE(SUBSTITUTE(SUBSTITUTE(SUBSTITUTE(SUBSTITUTE(SUBSTITUTE(C3,"1.5K",VO2max!B2),"3K",VO2max!C2),"5K",VO2max!D2),"10K",VO2max!E2),"21k",VO2max!F2),"42K",VO2max!G2),"ZA",VO2max!H2),"HL",VO2max!I2) -> zagrevanje 10min@7:30; 16x(100m@5:40 + 1min@7:30); hlađenje 5min@7:30 | D16: =VLOOKUP(D3,Legenda!$A$1:$B$51,2,FALSE) -> 5k@6:00 ili odmor | E16: =SUBSTITUTE(SUBSTITUTE(SUBSTITUTE(SUBSTITUTE(SUBSTITUTE(SUBSTITUTE(SUBSTITUTE(SUBSTITUTE(E3,"1.5K",VO2max!B2),"3K",VO2max!C2),"5K",VO2max!D2),"10K",VO2max!E2),"21k",VO2max!F2),"42K",VO2max!G2),"ZA",VO2max!H2),"HL",VO2max!I2) -> zagrevanje 10min@7:30; 6x(800m@6:05 +30sec@7:30); hlađenje 5min@7:30 | F16: =VLOOKUP(F3,Legenda!$A$1:$B$51,2,FALSE) -> 5k@6:00 ili odmor | G16: =SUBSTITUTE(SUBSTITUTE(SUBSTITUTE(SUBSTITUTE(SUBSTITUTE(SUBSTITUTE(SUBSTITUTE(SUBSTITUTE(G3,"1.5K",VO2max!B2),"3K",VO2max!C2),"5K",VO2max!D2),"10K",VO2max!E2),"21K",VO2max!F2),"42K",VO2max!G2),"ZA",VO2max!H2),"HL",VO2max!I2) -> zagrevanje 10min@7:30; 2x(1600m@6:05+1min@7:30); hlađenje 5min@7:30 | H16: =VLOOKUP(H3,Legenda!$A$1:$B$51,2,FALSE) -> 14k@6:00
A17: 3 | B17: =VLOOKUP(B4,Legenda!$A$1:$B$51,2,FALSE) -> Plivanje, bicikla, šetanje, vežbe snage, ... | C17: =SUBSTITUTE(SUBSTITUTE(SUBSTITUTE(SUBSTITUTE(SUBSTITUTE(SUBSTITUTE(SUBSTITUTE(SUBSTITUTE(C4,"1.5K",VO2max!B2),"3K",VO2max!C2),"5K",VO2max!D2),"10K",VO2max!E2),"21k",VO2max!F2),"42K",VO2max!G2),"ZA",VO2max!H2),"HL",VO2max!I2) -> zagrevanje 10min@7:30; 4x(1600m@6:20 +2min@7:30); hlađenje 5min@7:30 | D17: =VLOOKUP(D4,Legenda!$A$1:$B$51,2,FALSE) -> 5k@6:00 ili odmor | E17: =SUBSTITUTE(SUBSTITUTE(SUBSTITUTE(SUBSTITUTE(SUBSTITUTE(SUBSTITUTE(SUBSTITUTE(SUBSTITUTE(E4,"1.5K",VO2max!B2),"3K",VO2max!C2),"5K",VO2max!D2),"10K",VO2max!E2),"21k",VO2max!F2),"42K",VO2max!G2),"ZA",VO2max!H2),"HL",VO2max!I2) -> zagrevanje 10min@7:30; 4x(200m@6:00 + 400m@6:05 + 4min@7:30) hlađenje 5min@7:30 | F17: =VLOOKUP(F4,Legenda!$A$1:$B$51,2,FALSE) -> 5k@6:00 ili odmor | G17: =SUBSTITUTE(SUBSTITUTE(SUBSTITUTE(SUBSTITUTE(SUBSTITUTE(SUBSTITUTE(SUBSTITUTE(SUBSTITUTE(G4,"1.5K",VO2max!B2),"3K",VO2max!C2),"5K",VO2max!D2),"10K",VO2max!E2),"21K",VO2max!F2),"42K",VO2max!G2),"ZA",VO2max!H2),"HL",VO2max!I2) -> zagrevanje 10min@7:30; 1x25min@6:05; hlađenje 5min@7:30 | H17: =VLOOKUP(H4,Legenda!$A$1:$B$51,2,FALSE) -> 14k@6:00
A18: 4 | B18: =VLOOKUP(B5,Legenda!$A$1:$B$51,2,FALSE) -> 5k@6:00 ili odmor | C18: =SUBSTITUTE(SUBSTITUTE(SUBSTITUTE(SUBSTITUTE(SUBSTITUTE(SUBSTITUTE(SUBSTITUTE(SUBSTITUTE(C5,"1.5K",VO2max!B2),"3K",VO2max!C2),"5K",VO2max!D2),"10K",VO2max!E2),"21k",VO2max!F2),"42K",VO2max!G2),"ZA",VO2max!H2),"HL",VO2max!I2) -> zagrevanje 10min@7:30; 10x(100m@5:40 + 2min@7:30); hlađenje 5min@7:30 | D18: =VLOOKUP(D5,Legenda!$A$1:$B$51,2,FALSE) -> 5k@6:00 ili odmor | E18: =SUBSTITUTE(SUBSTITUTE(SUBSTITUTE(SUBSTITUTE(SUBSTITUTE(SUBSTITUTE(SUBSTITUTE(SUBSTITUTE(E5,"1.5K",VO2max!B2),"3K",VO2max!C2),"5K",VO2max!D2),"10K",VO2max!E2),"21k",VO2max!F2),"42K",VO2max!G2),"ZA",VO2max!H2),"HL",VO2max!I2) -> zagrevanje 10min@7:30; 12x(400m@6:05 +15sec@7:30); hlađenje 5min@7:30 | F18: =VLOOKUP(F5,Legenda!$A$1:$B$51,2,FALSE) -> 5k@6:00 ili odmor | G18: =SUBSTITUTE(SUBSTITUTE(SUBSTITUTE(SUBSTITUTE(SUBSTITUTE(SUBSTITUTE(SUBSTITUTE(SUBSTITUTE(G5,"1.5K",VO2max!B2),"3K",VO2max!C2),"5K",VO2max!D2),"10K",VO2max!E2),"21K",VO2max!F2),"42K",VO2max!G2),"ZA",VO2max!H2),"HL",VO2max!I2) -> zagrevanje 10min@7:30; 2x(600m@6:00 +1000m@6:05 + 4min@7:30) hlađenje 5min@7:30 | H18: =VLOOKUP(H5,Legenda!$A$1:$B$51,2,FALSE) -> 14k@6:00
A19: 5 | B19: =VLOOKUP(B6,Legenda!$A$1:$B$51,2,FALSE) -> Plivanje, bicikla, šetanje, vežbe snage, ... | C19: =SUBSTITUTE(SUBSTITUTE(SUBSTITUTE(SUBSTITUTE(SUBSTITUTE(SUBSTITUTE(SUBSTITUTE(SUBSTITUTE(C6,"1.5K",VO2max!B2),"3K",VO2max!C2),"5K",VO2max!D2),"10K",VO2max!E2),"21k",VO2max!F2),"42K",VO2max!G2),"ZA",VO2max!H2),"HL",VO2max!I2) -> zagrevanje 10min@7:30; 3x(2km@6:20 +2min@7:30); hlađenje 5min@7:30 | D19: =VLOOKUP(D6,Legenda!$A$1:$B$51,2,FALSE) -> 5k@6:00 ili odmor | E19: =SUBSTITUTE(SUBSTITUTE(SUBSTITUTE(SUBSTITUTE(SUBSTITUTE(SUBSTITUTE(SUBSTITUTE(SUBSTITUTE(E6,"1.5K",VO2max!B2),"3K",VO2max!C2),"5K",VO2max!D2),"10K",VO2max!E2),"21k",VO2max!F2),"42K",VO2max!G2),"ZA",VO2max!H2),"HL",VO2max!I2) -> zagrevanje 10min@7:30; 6x(200m@5:40 + 400@6:00 + 4min@7:30) hlađenje 5min@7:30 | F19: =VLOOKUP(F6,Legenda!$A$1:$B$51,2,FALSE) -> 5k@6:00 ili odmor | G19: =SUBSTITUTE(SUBSTITUTE(SUBSTITUTE(SUBSTITUTE(SUBSTITUTE(SUBSTITUTE(SUBSTITUTE(SUBSTITUTE(G6,"1.5K",VO2max!B2),"3K",VO2max!C2),"5K",VO2max!D2),"10K",VO2max!E2),"21K",VO2max!F2),"42K",VO2max!G2),"ZA",VO2max!H2),"HL",VO2max!I2) -> zagrevanje 10min@7:30; 1x30min@6:05; hlađenje 5min@7:30 | H19: =VLOOKUP(H6,Legenda!$A$1:$B$51,2,FALSE) -> 14k@6:00
A20: 6 | B20: =VLOOKUP(B7,Legenda!$A$1:$B$51,2,FALSE) -> 5k@6:00 ili odmor | C20: =SUBSTITUTE(SUBSTITUTE(SUBSTITUTE(SUBSTITUTE(SUBSTITUTE(SUBSTITUTE(SUBSTITUTE(SUBSTITUTE(C7,"1.5K",VO2max!B2),"3K",VO2max!C2),"5K",VO2max!D2),"10K",VO2max!E2),"21k",VO2max!F2),"42K",VO2max!G2),"ZA",VO2max!H2),"HL",VO2max!I2) -> zagrevanje 10min@7:30; 8x(200m@5:40 + 1min@7:30); hlađenje 5min@7:30 | D20: =VLOOKUP(D7,Legenda!$A$1:$B$51,2,FALSE) -> progresivno aerobno trčanje u 3 jednaka segmenta, od sporijeg ka bržem | E20: =SUBSTITUTE(SUBSTITUTE(SUBSTITUTE(SUBSTITUTE(SUBSTITUTE(SUBSTITUTE(SUBSTITUTE(SUBSTITUTE(E7,"1.5K",VO2max!B2),"3K",VO2max!C2),"5K",VO2max!D2),"10K",VO2max!E2),"21k",VO2max!F2),"42K",VO2max!G2),"ZA",VO2max!H2),"HL",VO2max!I2) -> zagrevanje 10min@7:30; 3x(6min@6:20 +3min@7:30); hlađenje 5min@7:30 | F20: =VLOOKUP(F7,Legenda!$A$1:$B$51,2,FALSE) -> 5k@6:00 ili odmor | G20: =SUBSTITUTE(SUBSTITUTE(SUBSTITUTE(SUBSTITUTE(SUBSTITUTE(SUBSTITUTE(SUBSTITUTE(SUBSTITUTE(G7,"1.5K",VO2max!B2),"3K",VO2max!C2),"5K",VO2max!D2),"10K",VO2max!E2),"21K",VO2max!F2),"42K",VO2max!G2),"ZA",VO2max!H2),"HL",VO2max!I2) -> zagrevanje 10min@7:30; 3x(1600m@6:05 +1min@7:30); hlađenje 5min@7:30 | H20: =VLOOKUP(H7,Legenda!$A$1:$B$51,2,FALSE) -> 14k@6:00
A21: 7 | B21: =VLOOKUP(B8,Legenda!$A$1:$B$51,2,FALSE) -> Plivanje, bicikla, šetanje, vežbe snage, ... | C21: =SUBSTITUTE(SUBSTITUTE(SUBSTITUTE(SUBSTITUTE(SUBSTITUTE(SUBSTITUTE(SUBSTITUTE(SUBSTITUTE(C8,"1.5K",VO2max!B2),"3K",VO2max!C2),"5K",VO2max!D2),"10K",VO2max!E2),"21k",VO2max!F2),"42K",VO2max!G2),"ZA",VO2max!H2),"HL",VO2max!I2) -> zagrevanje 10min@7:30; 5x(1km@6:05 + 1min@7:30); hlađenje 5min@7:30 | D21: =VLOOKUP(D8,Legenda!$A$1:$B$51,2,FALSE) -> 5k@6:00 ili odmor | E21: =SUBSTITUTE(SUBSTITUTE(SUBSTITUTE(SUBSTITUTE(SUBSTITUTE(SUBSTITUTE(SUBSTITUTE(SUBSTITUTE(E8,"1.5K",VO2max!B2),"3K",VO2max!C2),"5K",VO2max!D2),"10K",VO2max!E2),"21k",VO2max!F2),"42K",VO2max!G2),"ZA",VO2max!H2),"HL",VO2max!I2) -> zagrevanje 10min@7:30; 8x(200m@6:00 +1min@7:30); hlađenje 5min@7:30 | F21: =VLOOKUP(F8,Legenda!$A$1:$B$51,2,FALSE) -> 5k@6:00 ili odmor | G21: =SUBSTITUTE(SUBSTITUTE(SUBSTITUTE(SUBSTITUTE(SUBSTITUTE(SUBSTITUTE(SUBSTITUTE(SUBSTITUTE(G8,"1.5K",VO2max!B2),"3K",VO2max!C2),"5K",VO2max!D2),"10K",VO2max!E2),"21K",VO2max!F2),"42K",VO2max!G2),"ZA",VO2max!H2),"HL",VO2max!I2) -> odmor | H21: =VLOOKUP(H8,Legenda!$A$1:$B$51,2,FALSE) -> 0
A22: 8 | B22: =VLOOKUP(B9,Legenda!$A$1:$B$51,2,FALSE) -> 5k@6:00 ili odmor | C22: =SUBSTITUTE(SUBSTITUTE(SUBSTITUTE(SUBSTITUTE(SUBSTITUTE(SUBSTITUTE(SUBSTITUTE(SUBSTITUTE(C9,"1.5K",VO2max!B2),"3K",VO2max!C2),"5K",VO2max!D2),"10K",VO2max!E2),"21k",VO2max!F2),"42K",VO2max!G2),"ZA",VO2max!H2),"HL",VO2max!I2) -> zagrevanje 10min@7:30; 8x(100m@5:40 + 2min@7:30); hlađenje 5min@7:30 | D22: =VLOOKUP(D9,Legenda!$A$1:$B$51,2,FALSE) -> 5k@6:00 ili odmor | E22: =SUBSTITUTE(SUBSTITUTE(SUBSTITUTE(SUBSTITUTE(SUBSTITUTE(SUBSTITUTE(SUBSTITUTE(SUBSTITUTE(E9,"1.5K",VO2max!B2),"3K",VO2max!C2),"5K",VO2max!D2),"10K",VO2max!E2),"21k",VO2max!F2),"42K",VO2max!G2),"ZA",VO2max!H2),"HL",VO2max!I2) -> zagrevanje 10min@7:30; 6x(800m@6:05 +30sec@7:30); hlađenje 5min@7:30 | F22: =VLOOKUP(F9,Legenda!$A$1:$B$51,2,FALSE) -> 5k@6:00 ili odmor | G22: =SUBSTITUTE(SUBSTITUTE(SUBSTITUTE(SUBSTITUTE(SUBSTITUTE(SUBSTITUTE(SUBSTITUTE(SUBSTITUTE(G9,"1.5K",VO2max!B2),"3K",VO2max!C2),"5K",VO2max!D2),"10K",VO2max!E2),"21K",VO2max!F2),"42K",VO2max!G2),"ZA",VO2max!H2),"HL",VO2max!I2) -> zagrevanje 10min@7:30; 3x(600m@6:05 +1000m@6:20+4min@7:30); hlađenje 5min@7:30 | H22: =VLOOKUP(H9,Legenda!$A$1:$B$51,2,FALSE) -> 14k@6:00
A23: 9 | B23: =VLOOKUP(B10,Legenda!$A$1:$B$51,2,FALSE) -> Plivanje, bicikla, šetanje, vežbe snage, ... | C23: =SUBSTITUTE(SUBSTITUTE(SUBSTITUTE(SUBSTITUTE(SUBSTITUTE(SUBSTITUTE(SUBSTITUTE(SUBSTITUTE(C10,"1.5K",VO2max!B2),"3K",VO2max!C2),"5K",VO2max!D2),"10K",VO2max!E2),"21k",VO2max!F2),"42K",VO2max!G2),"ZA",VO2max!H2),"HL",VO2max!I2) -> zagrevanje 10min@7:30; 2x(2k@6:05 + 2min@7:30); hlađenje 5min@7:30 | D23: =VLOOKUP(D10,Legenda!$A$1:$B$51,2,FALSE) -> 5k@6:00 ili odmor | E23: =SUBSTITUTE(SUBSTITUTE(SUBSTITUTE(SUBSTITUTE(SUBSTITUTE(SUBSTITUTE(SUBSTITUTE(SUBSTITUTE(E10,"1.5K",VO2max!B2),"3K",VO2max!C2),"5K",VO2max!D2),"10K",VO2max!E2),"21k",VO2max!F2),"42K",VO2max!G2),"ZA",VO2max!H2),"HL",VO2max!I2) -> zagrevanje 10min@7:30; 5x(3min@6:00 + 3min@7:30); hlađenje 5min@7:30 | F23: =VLOOKUP(F10,Legenda!$A$1:$B$51,2,FALSE) -> 5k@6:00 ili odmor | G23: =SUBSTITUTE(SUBSTITUTE(SUBSTITUTE(SUBSTITUTE(SUBSTITUTE(SUBSTITUTE(SUBSTITUTE(SUBSTITUTE(G10,"1.5K",VO2max!B2),"3K",VO2max!C2),"5K",VO2max!D2),"10K",VO2max!E2),"21K",VO2max!F2),"42K",VO2max!G2),"ZA",VO2max!H2),"HL",VO2max!I2) -> zagrevanje 10min@7:30; 30min@6:20; hlađenje 5min@7:30 | H23: =VLOOKUP(H10,Legenda!$A$1:$B$51,2,FALSE) -> 14k@6:00
A24: 10 | B24: =VLOOKUP(B11,Legenda!$A$1:$B$51,2,FALSE) -> 5k@6:00, 4-6 x 100m ubrzanja na kraju treninga | C24: =SUBSTITUTE(SUBSTITUTE(SUBSTITUTE(SUBSTITUTE(SUBSTITUTE(SUBSTITUTE(SUBSTITUTE(SUBSTITUTE(C11,"1.5K",VO2max!B2),"3K",VO2max!C2),"5K",VO2max!D2),"10K",VO2max!E2),"21k",VO2max!F2),"42K",VO2max!G2),"ZA",VO2max!H2),"HL",VO2max!I2) -> zagrevanje 10min@7:30; 10x(200m@5:40 + 2min@7:30); hlađenje 5min@7:30 | D24: =VLOOKUP(D11,Legenda!$A$1:$B$51,2,FALSE) -> progresivno aerobno trčanje u 3 jednaka segmenta, od sporijeg ka bržem | E24: =SUBSTITUTE(SUBSTITUTE(SUBSTITUTE(SUBSTITUTE(SUBSTITUTE(SUBSTITUTE(SUBSTITUTE(SUBSTITUTE(E11,"1.5K",VO2max!B2),"3K",VO2max!C2),"5K",VO2max!D2),"10K",VO2max!E2),"21k",VO2max!F2),"42K",VO2max!G2),"ZA",VO2max!H2),"HL",VO2max!I2) -> zagrevanje 10min@7:30; 5x(1k@6:05 + 1min@7:30); hlađenje 5min@7:30 | F24: =VLOOKUP(F11,Legenda!$A$1:$B$51,2,FALSE) -> 5k@6:00 ili odmor | G24: =SUBSTITUTE(SUBSTITUTE(SUBSTITUTE(SUBSTITUTE(SUBSTITUTE(SUBSTITUTE(SUBSTITUTE(SUBSTITUTE(G11,"1.5K",VO2max!B2),"3K",VO2max!C2),"5K",VO2max!D2),"10K",VO2max!E2),"21K",VO2max!F2),"42K",VO2max!G2),"ZA",VO2max!H2),"HL",VO2max!I2) -> zagrevanje 10min@7:30; 4x(400m@6:00 +400m@6:05 + 3min@7:30) hlađenje 5min@7:30 | H24: =VLOOKUP(H11,Legenda!$A$1:$B$51,2,FALSE) -> 14k@6:00
A25: 11 | B25: =VLOOKUP(B12,Legenda!$A$1:$B$51,2,FALSE) -> 5k@6:00 ili odmor | C25: =SUBSTITUTE(SUBSTITUTE(SUBSTITUTE(SUBSTITUTE(SUBSTITUTE(SUBSTITUTE(SUBSTITUTE(SUBSTITUTE(C12,"1.5K",VO2max!B2),"3K",VO2max!C2),"5K",VO2max!D2),"10K",VO2max!E2),"21k",VO2max!F2),"42K",VO2max!G2),"ZA",VO2max!H2),"HL",VO2max!I2) -> zagrevanje 10min@7:30; 6x(1k@6:20 + 1min@7:30); hlađenje 5min@7:30 | D25: =VLOOKUP(D12,Legenda!$A$1:$B$51,2,FALSE) -> 5k@6:00 ili odmor | E25: =SUBSTITUTE(SUBSTITUTE(SUBSTITUTE(SUBSTITUTE(SUBSTITUTE(SUBSTITUTE(SUBSTITUTE(SUBSTITUTE(E12,"1.5K",VO2max!B2),"3K",VO2max!C2),"5K",VO2max!D2),"10K",VO2max!E2),"21k",VO2max!F2),"42K",VO2max!G2),"ZA",VO2max!H2),"HL",VO2max!I2) -> zagrevanje 10min@7:30; 5x(3min@6:00 + 3min@7:30); hlađenje 5min@7:30 | F25: =VLOOKUP(F12,Legenda!$A$1:$B$51,2,FALSE) -> 5k@6:00 ili odmor | G25: =SUBSTITUTE(SUBSTITUTE(SUBSTITUTE(SUBSTITUTE(SUBSTITUTE(SUBSTITUTE(SUBSTITUTE(SUBSTITUTE(G12,"1.5K",VO2max!B2),"3K",VO2max!C2),"5K",VO2max!D2),"10K",VO2max!E2),"21K",VO2max!F2),"42K",VO2max!G2),"ZA",VO2max!H2),"HL",VO2max!I2) -> odmor | H25: =VLOOKUP(H12,Legenda!$A$1:$B$51,2,FALSE) -> 0
A26: 12 | B26: =VLOOKUP(B13,Legenda!$A$1:$B$51,2,FALSE) -> 5k@6:00 ili odmor | C26: =SUBSTITUTE(SUBSTITUTE(SUBSTITUTE(SUBSTITUTE(SUBSTITUTE(SUBSTITUTE(SUBSTITUTE(SUBSTITUTE(C13,"1.5K",VO2max!B3),"3K",VO2max!C3),"5K",VO2max!D3),"10K",VO2max!E3),"21k",VO2max!F3),"42K",VO2max!G3),"ZA",VO2max!H3),"HL",VO2max!I3) -> zagrevanje 10min@; 10min@; hlađenje 5min@ | D26: =VLOOKUP(D13,Legenda!$A$1:$B$51,2,FALSE) -> Plivanje, bicikla, šetanje, vežbe snage, ... | E26: =SUBSTITUTE(SUBSTITUTE(SUBSTITUTE(SUBSTITUTE(SUBSTITUTE(SUBSTITUTE(SUBSTITUTE(SUBSTITUTE(E13,"1.5K",VO2max!B3),"3K",VO2max!C3),"5K",VO2max!D3),"10K",VO2max!E3),"21k",VO2max!F3),"42K",VO2max!G3),"ZA",VO2max!H3),"HL",VO2max!I3) -> zagrevanje 10min@; 3x(1.5min@ + 1.5min@); hlađenje 5min@ | F26: =VLOOKUP(F13,Legenda!$A$1:$B$51,2,FALSE) -> odmor | G26: =SUBSTITUTE(SUBSTITUTE(SUBSTITUTE(SUBSTITUTE(SUBSTITUTE(SUBSTITUTE(SUBSTITUTE(SUBSTITUTE(G13,"1.5K",VO2max!B3),"3K",VO2max!C3),"5K",VO2max!D3),"10K",VO2max!E3),"21K",VO2max!F3),"42K",VO2max!G3),"ZA",VO2max!H3),"HL",VO2max!I3) -> 3k@; 3x100m ubrzanja Ubrzanja se trče po ravnoj stazi i sa snagom od 85%. U pauzi se ili hoda ili lagano trči i ne počinje se ponovo dok se potpuno ne odmori. | H26: =VLOOKUP(H13,Legenda!$A$1:$B$51,2,FALSE) -> 0

Sheet 5kB-templ
A1: Nedelja | B1: DAN | C1: Trening | G1: Nedelja | H1: DAN | I1: Trening
A2: 1 | B2: Ponedeljak | C2: ='5kB'!B15 -> Plivanje, bicikla, šetanje, vežbe snage, ... | G2: 1 | H2: Ponedeljak | I2: Plivanje, bicikla, šetanje, vežbe snage, ...
B3: Utorak | C3: ='5kB'!C15 -> zagrevanje 10min@7:30; 3x(1200m@6:20 +2min@7:30); hlađenje 5min@7:30 | H3: Utorak | I3: zagrevanje 10min@7:30; 3x(1200m@6:20 +2min@7:30); hlađenje 5min@7:30
B4: Sreda | C4: ='5kB'!D15 -> 5k@6:00 ili odmor | H4: Sreda | I4: 5k@6:00 ili odmor
B5: Četvrtak | C5: ='5kB'!E15 -> zagrevanje 10min@7:30; 8x(200m@6:05 +1min@7:30); hlađenje 5min@7:30 | H5: Četvrtak | I5: zagrevanje 10min@7:30; 8x(200m@6:05 +1min@7:30); hlađenje 5min@7:30
B6: Petak | C6: ='5kB'!F15 -> 5k@6:00 ili odmor | H6: Petak | I6: 5k@6:00 ili odmor
B7: Subota | C7: ='5kB'!G15 -> zagrevanje 10min@7:30; 1x20min@6:40; hlađenje 5min@7:30 | H7: Subota | I7: zagrevanje 10min@7:30; 1x20min@6:40; hlađenje 5min@7:30
B8: Nedelja | C8: ='5kB'!H15 -> 14k@6:00 | H8: Nedelja | I8: 14k@6:00
A9: Nedelja | B9: DAN | C9: Trening | G9: Nedelja | H9: DAN | I9: Trening
A10: 2 | B10: Ponedeljak | C10: ='5kB'!B16 -> 5k@6:00 ili odmor | G10: 2 | H10: Ponedeljak | I10: 5k@6:00 ili odmor
B11: Utorak | C11: ='5kB'!C16 -> zagrevanje 10min@7:30; 16x(100m@5:40 + 1min@7:30); hlađenje 5min@7:30 | H11: Utorak | I11: zagrevanje 10min@7:30; 16x(100m@5:40 + 1min@7:30); hlađenje 5min@7:30
B12: Sreda | C12: ='5kB'!D16 -> 5k@6:00 ili odmor | H12: Sreda | I12: 5k@6:00 ili odmor
B13: Četvrtak | C13: ='5kB'!E16 -> zagrevanje 10min@7:30; 6x(800m@6:05 +30sec@7:30); hlađenje 5min@7:30 | H13: Četvrtak | I13: zagrevanje 10min@7:30; 6x(800m@6:05 +30sec@7:30); hlađenje 5min@7:30
B14: Petak | C14: ='5kB'!F16 -> 5k@6:00 ili odmor | H14: Petak | I14: 5k@6:00 ili odmor
B15: Subota | C15: ='5kB'!G16 -> zagrevanje 10min@7:30; 2x(1600m@6:05+1min@7:30); hlađenje 5min@7:30 | H15: Subota | I15: zagrevanje 10min@7:30; 2x(1600m@6:05+1min@7:30); hlađenje 5min@7:30
B16: Nedelja | C16: ='5kB'!H16 -> 14k@6:00 | H16: Nedelja | I16: 14k@6:00
A17: Nedelja | B17: DAN | C17: Trening | G17: Nedelja | H17: DAN | I17: Trening
A18: 3 | B18: Ponedeljak | C18: ='5kB'!B17 -> Plivanje, bicikla, šetanje, vežbe snage, ... | G18: 3 | H18: Ponedeljak | I18: Plivanje, bicikla, šetanje, vežbe snage, ...
B19: Utorak | C19: ='5kB'!C17 -> zagrevanje 10min@7:30; 4x(1600m@6:20 +2min@7:30); hlađenje 5min@7:30 | H19: Utorak | I19: zagrevanje 10min@7:30; 4x(1600m@6:20 +2min@7:30); hlađenje 5min@7:30
B20: Sreda | C20: ='5kB'!D17 -> 5k@6:00 ili odmor | H20: Sreda | I20: 5k@6:00 ili odmor
B21: Četvrtak | C21: ='5kB'!E17 -> zagrevanje 10min@7:30; 4x(200m@6:00 + 400m@6:05 + 4min@7:30) hlađenje 5min@7:30 | H21: Četvrtak | I21: zagrevanje 10min@7:30; 4x(200m@6:00 + 400m@6:05 + 4min@7:30) hlađenje 5min@7:30
B22: Petak | C22: ='5kB'!F17 -> 5k@6:00 ili odmor | H22: Petak | I22: 5k@6:00 ili odmor
B23: Subota | C23: ='5kB'!G17 -> zagrevanje 10min@7:30; 1x25min@6:05; hlađenje 5min@7:30 | H23: Subota | I23: zagrevanje 10min@7:30; 1x25min@6:05; hlađenje 5min@7:30
B24: Nedelja | C24: ='5kB'!H17 -> 14k@6:00 | H24: Nedelja | I24: 14k@6:00
A25: Nedelja | B25: DAN | C25: Trening | G25: Nedelja | H25: DAN | I25: Trening
A26: 4 | B26: Ponedeljak | C26: ='5kB'!B18 -> 5k@6:00 ili odmor | G26: 4 | H26: Ponedeljak | I26: 5k@6:00 ili odmor
B27: Utorak | C27: ='5kB'!C18 -> zagrevanje 10min@7:30; 10x(100m@5:40 + 2min@7:30); hlađenje 5min@7:30 | H27: Utorak | I27: zagrevanje 10min@7:30; 10x(100m@5:40 + 2min@7:30); hlađenje 5min@7:30
B28: Sreda | C28: ='5kB'!D18 -> 5k@6:00 ili odmor | H28: Sreda | I28: 5k@6:00 ili odmor
B29: Četvrtak | C29: ='5kB'!E18 -> zagrevanje 10min@7:30; 12x(400m@6:05 +15sec@7:30); hlađenje 5min@7:30 | H29: Četvrtak | I29: zagrevanje 10min@7:30; 12x(400m@6:05 +15sec@7:30); hlađenje 5min@7:30
B30: Petak | C30: ='5kB'!F18 -> 5k@6:00 ili odmor | H30: Petak | I30: 5k@6:00 ili odmor
B31: Subota | C31: ='5kB'!G18 -> zagrevanje 10min@7:30; 2x(600m@6:00 +1000m@6:05 + 4min@7:30) hlađenje 5min@7:30 | H31: Subota | I31: zagrevanje 10min@7:30; 2x(600m@6:00 +1000m@6:05 + 4min@7:30) hlađenje 5min@7:30
B32: Nedelja | C32: ='5kB'!H18 -> 14k@6:00 | H32: Nedelja | I32: 14k@6:00
A33: Nedelja | B33: DAN | C33: Trening | G33: Nedelja | H33: DAN | I33: Trening
A34: 5 | B34: Ponedeljak | C34: ='5kB'!B19 -> Plivanje, bicikla, šetanje, vežbe snage, ... | G34: 5 | H34: Ponedeljak | I34: Plivanje, bicikla, šetanje, vežbe snage, ...
B35: Utorak | C35: ='5kB'!C19 -> zagrevanje 10min@7:30; 3x(2km@6:20 +2min@7:30); hlađenje 5min@7:30 | H35: Utorak | I35: zagrevanje 10min@7:30; 3x(2km@6:20 +2min@7:30); hlađenje 5min@7:30
B36: Sreda | C36: ='5kB'!D19 -> 5k@6:00 ili odmor | H36: Sreda | I36: 5k@6:00 ili odmor
B37: Četvrtak | C37: ='5kB'!E19 -> zagrevanje 10min@7:30; 6x(200m@5:40 + 400@6:00 + 4min@7:30) hlađenje 5min@7:30 | H37: Četvrtak | I37: zagrevanje 10min@7:30; 6x(200m@5:40 + 400@6:00 + 4min@7:30) hlađenje 5min@7:30
B38: Petak | C38: ='5kB'!F19 -> 5k@6:00 ili odmor | H38: Petak | I38: 5k@6:00 ili odmor
B39: Subota | C39: ='5kB'!G19 -> zagrevanje 10min@7:30; 1x30min@6:05; hlađenje 5min@7:30 | H39: Subota | I39: zagrevanje 10min@7:30; 1x30min@6:05; hlađenje 5min@7:30
B40: Nedelja | C40: ='5kB'!H19 -> 14k@6:00 | H40: Nedelja | I40: 14k@6:00
...

Sheet 21kC-proba
A1: Nedelja | B1: PO | C1: UT | D1: SR | E1: CE | F1: PE | G1: SU | H1: NE | K1: Vo2max | L1: 1.5K | M1: 3K | N1: 5K | O1: 10k | P1: 21k | Q1: 42k | R1: 1.5K pace | S1: 3K pace | T1: 5K pace | U1: 10kpace | V1: 21kpace | W1: 42kpace
A2: 1 | B2: A | C2: 2x10min@10K +4min odmor | K2: 45 | L2: 5:56 | M2: 12:40 | N2: 21:50 | O2: 45:16 | P2: 1:40:20 | Q2: 3:28:26 | R2: =L2/1.5 -> 0.16481481 | S2: =M2/3 -> 0.17592593 | T2: =N2/5 -> 0.18194444 | U2: =O2/10 -> 0.18861111 | V2: =MID(TEXT(P2/21.1,"hh:mm:ss"),5,7) -> 4:45 | W2: =MID(TEXT(Q2/42.2,"hh:mm:ss"),5,7) -> 4:56
K3: 46 | L3: 0.24236111 | M3: 0.51805556 | N3: 0.89236111 | O3: 44:25 | P3: 1:38:27 | Q3: 3:24:39
A9: Nedelja | B9: PO | C9: UT | D9: SR | E9: CE | F9: PE | G9: SU | H9: NE | I9: pom10k | J9: pom10k | K9: pom10k | L9: pom5k
C10: =SUBSTITUTE(C2,"10K",J10) -> #REF! | I10: =VLOOKUP(VO2max!A2,K:W,11,FALSE) -> #REF! | J10: =MID(TEXT(I10,"hh:mm:ss AM/PM"),2,4) -> #REF! | K10: =MID(TEXT(VLOOKUP(VO2max!A2,K:W,11,FALSE),"hh:mm:ss AM/PM"),2,4) -> #REF!
C13: =SUBSTITUTE(C2,"10K",J13) -> 2x10min@5:00 +4min odmor | I13: =VLOOKUP(VO2max!A2,VO2maxPace!$A$1:$M$50,11,FALSE) -> 0.20854167 | J13: =MID(TEXT(I13,"hh:mm:ss AM/PM"),2,4) -> 5:00 | K13: =MID(TEXT(VLOOKUP(VO2max!A2,VO2maxPace!$A$1:$M$50,11,FALSE),"hh:mm:ss AM/PM"),2,4) -> 5:00
I15: =VO2maxPace!A2 -> 45
C16: =SUBSTITUTE(SUBSTITUTE(SUBSTITUTE(SUBSTITUTE(SUBSTITUTE(SUBSTITUTE(C2,"1.5K",VO2max!B2),"3K",VO2max!C2),"5K",VO2max!D2),"10K",VO2max!E2),"21k",VO2max!F2),"42K",VO2max!G2) -> 2x10min@6:20 +4min odmor
C18: =VO2max!E2 -> 6:20

Sheet 21kC
A1: Nedelja | B1: PO | C1: UT | D1: SR | E1: CE | F1: PE | G1: SU | H1: NE
A2: 1 | B2: A | C2: zagrevanje 15min@ZA; 2x10min@10K +4min odmor; hlađenje 10min@HL
A9: Nedelja | B9: PO | C9: UT | D9: SR | E9: CE | F9: PE | G9: SU | H9: NE
A10: 1 | C10: =SUBSTITUTE(SUBSTITUTE(SUBSTITUTE(SUBSTITUTE(SUBSTITUTE(SUBSTITUTE(SUBSTITUTE(SUBSTITUTE(C2,"1.5K",VO2max!B2),"3K",VO2max!C2),"5K",VO2max!D2),"10K",VO2max!E2),"21k",VO2max!F2),"42K",VO2max!G2),"ZA",VO2max!H2),"HL",VO2max!I2) -> zagrevanje 15min@7:30; 2x10min@6:20 +4min odmor; hlađenje 10min@7:30

Sheet 21kB
A1: Nedelja | B1: PO | C1: UT | D1: SR | E1: CE | F1: PE | G1: SU | H1: NE
A2: 1 | B2: XT | C2: zagrevanje 15min@ZA; 2x(10min@10K +4min@ZA); hlađenje 10min@HL | D2: A | E2: zagrevanje 15min@ZA; 8x(400m@5K +1min@ZA); hlađenje 10min@HL | F2: E | G2: zagrevanje 15min@ZA; 1x30min@21K; hlađenje 10min@HL | H2: L
A3: 2 | B3: E | C3: zagrevanje 15min@ZA; 16x(100m@3K + 1min@ZA); hlađenje 10min@HL | D3: A | E3: zagrevanje 15min@ZA; 6x(800m@5K +30sec@ZA); hlađenje 10min@HL | F3: E | G3: zagrevanje 15min@ZA; 2x(3km@10K+4min@ZA); hlađenje 10min@HL | H3: L1
A4: 3 | B4: XT | C4: zagrevanje 15min@ZA; 3x(10min@10K +4min@ZA); hlađenje 10min@HL | D4: A | E4: zagrevanje 15min@ZA; 2x(800m@10K + 600m@5K + 4min@ZA) hlađenje 10min@HL | F4: E | G4: zagrevanje 15min@ZA; 1x40min@21K; hlađenje 10min@HL | H4: L
A5: 4 | B5: E | C5: zagrevanje 15min@ZA; 10x(200m@5K + 2min@ZA); hlađenje 10min@HL | D5: A | E5: zagrevanje 15min@ZA; 12x(400m@5K +15sec@ZA); hlađenje 10min@HL | F5: E | G5: zagrevanje 15min@ZA; 2x(400m@5K +800m@10K+3200m@21K + 4min@ZA) hlađenje 10min@HL | H5: L1
A6: 5 | B6: XT | C6: zagrevanje 15min@ZA; 4x(2km@10K +3min@ZA); hlađenje 10min@HL | D6: A | E6: zagrevanje 15min@ZA; 2x(200m@1.5K + 400@3K + 4min@ZA) hlađenje 10min@HL | F6: E | G6: zagrevanje 15min@ZA; 1x50min@21K; hlađenje 10min@HL | H6: L
A7: 6 | B7: E | C7: zagrevanje 15min@ZA; 10x(200m@3K + 1min@ZA); hlađenje 10min@HL | D7: A1 | E7: zagrevanje 15min@ZA; 4x(8min@10K +4min@ZA); hlađenje 10min@HL | F7: E | G7: zagrevanje 15min@ZA; 3x(1600m@5K +1min@ZA); hlađenje 10min@HL | H7: L1
A8: 7 | B8: XT | C8: zagrevanje 15min@ZA; 7x(1km@10K + 1min@ZA); hlađenje 10min@HL | D8: A | E8: zagrevanje 15min@ZA; 8x(200m@3K +1min@ZA); hlađenje 10min@HL | F8: E | G8: odmor | H8: zagrevanje 10min@ZA; 10k@10K; hlađenje 10min@HL
A9: 8 | B9: E | C9: zagrevanje 15min@ZA; 8x(100m@3K + 2min@ZA); hlađenje 10min@HL | D9: A | E9: zagrevanje 15min@ZA; 6x(800m@5K +30sec@ZA); hlađenje 10min@HL | F9: E | G9: zagrevanje 15min@ZA; 3x(400m@5K +800m@10K+3200m@21K+4min@ZA); hlađenje 10min@HL | H9: L1
A10: 9 | B10: XT | C10: zagrevanje 15min@ZA; 4x(2k@10K + 2min@ZA); hlađenje 10min@HL | D10: A | E10: zagrevanje 15min@ZA; 5x(3min@3K + 3min@ZA); hlađenje 10min@HL | F10: E | G10: zagrevanje 10min@ZA; 60min@21K; hlađenje 10min@HL | H10: L
A11: 10 | B11: E1 | C11: zagrevanje 15min@ZA; 12x(200m@3K + 1min@ZA); hlađenje 10min@HL | D11: A1 | E11: zagrevanje 15min@ZA; 7x(1k@10K + 2min@ZA); hlađenje 10min@HL | F11: E | G11: zagrevanje 10min@ZA; 30min@21K; hlađenje 10min@HL | H11: L
A12: 11 | B12: E | C12: zagrevanje 15min@ZA; 7x(1k@10K + 1min@ZA); hlađenje 10min@HL | D12: A | E12: zagrevanje 15min@ZA; 5x(3min@3K + 3min@ZA); hlađenje 10min@HL | F12: E | G12: odmor | H12: zagrevanje 10min@ZA; 5k@5K; hlađenje 10min@HL
A13: 12 | B13: A | C13: zagrevanje 10min@ZA; 20min@21K; hlađenje 10min@HL | D13: XT | E13: zagrevanje 15min@ZA; 3x(1.5min@5K + 1.5min@ZA); hlađenje 10min@HL | F13: odmor | G13: 3k@ZA; 3x100m ubrzanja Ubrzanja se trče po ravnoj stazi i sa snagom od 85%. U pauzi se ili hoda ili lagano trči i ne počinje se ponovo dok se potpuno ne odmori. | H13: Obavezno uraditi zagrevanje laganim trčanjem na samom startu barem 1km Trka: 21.1km
A14: Nedelja | B14: PO | C14: UT | D14: SR | E14: CE | F14: PE | G14: SU | H14: NE
A15: 1 | B15: =VLOOKUP(B2,Legenda!$A$1:$B$51,2,FALSE) -> Plivanje, bicikla, šetanje, vežbe snage, ... | C15: =SUBSTITUTE(SUBSTITUTE(SUBSTITUTE(SUBSTITUTE(SUBSTITUTE(SUBSTITUTE(SUBSTITUTE(SUBSTITUTE(C2,"1.5K",VO2max!B2),"3K",VO2max!C2),"5K",VO2max!D2),"10K",VO2max!E2),"21k",VO2max!F2),"42K",VO2max!G2),"ZA",VO2max!H2),"HL",VO2max!I2) -> zagrevanje 15min@7:30; 2x(10min@6:20 +4min@7:30); hlađenje 10min@7:30 | D15: =VLOOKUP(D2,Legenda!$A$1:$B$51,2,FALSE) -> 5k@6:00 ili odmor | E15: =SUBSTITUTE(SUBSTITUTE(SUBSTITUTE(SUBSTITUTE(SUBSTITUTE(SUBSTITUTE(SUBSTITUTE(SUBSTITUTE(E2,"1.5K",VO2max!B2),"3K",VO2max!C2),"5K",VO2max!D2),"10K",VO2max!E2),"21k",VO2max!F2),"42K",VO2max!G2),"ZA",VO2max!H2),"HL",VO2max!I2) -> zagrevanje 15min@7:30; 8x(400m@6:05 +1min@7:30); hlađenje 10min@7:30 | F15: =VLOOKUP(F2,Legenda!$A$1:$B$51,2,FALSE) -> 5k@6:00 ili odmor | G15: =SUBSTITUTE(SUBSTITUTE(SUBSTITUTE(SUBSTITUTE(SUBSTITUTE(SUBSTITUTE(SUBSTITUTE(SUBSTITUTE(G2,"1.5K",VO2max!B2),"3K",VO2max!C2),"5K",VO2max!D2),"10K",VO2max!E2),"21K",VO2max!F2),"42K",VO2max!G2),"ZA",VO2max!H2),"HL",VO2max!I2) -> zagrevanje 15min@7:30; 1x30min@6:40; hlađenje 10min@7:30 | H15: =VLOOKUP(H2,Legenda!$A$1:$B$51,2,FALSE) -> 14k@6:00
A16: 2 | B16: =VLOOKUP(B3,Legenda!$A$1:$B$51,2,FALSE) -> 5k@6:00 ili odmor | C16: =SUBSTITUTE(SUBSTITUTE(SUBSTITUTE(SUBSTITUTE(SUBSTITUTE(SUBSTITUTE(SUBSTITUTE(SUBSTITUTE(C3,"1.5K",VO2max!B2),"3K",VO2max!C2),"5K",VO2max!D2),"10K",VO2max!E2),"21k",VO2max!F2),"42K",VO2max!G2),"ZA",VO2max!H2),"HL",VO2max!I2) -> zagrevanje 15min@7:30; 16x(100m@6:00 + 1min@7:30); hlađenje 10min@7:30 | D16: =VLOOKUP(D3,Legenda!$A$1:$B$51,2,FALSE) -> 5k@6:00 ili odmor | E16: =SUBSTITUTE(SUBSTITUTE(SUBSTITUTE(SUBSTITUTE(SUBSTITUTE(SUBSTITUTE(SUBSTITUTE(SUBSTITUTE(E3,"1.5K",VO2max!B2),"3K",VO2max!C2),"5K",VO2max!D2),"10K",VO2max!E2),"21k",VO2max!F2),"42K",VO2max!G2),"ZA",VO2max!H2),"HL",VO2max!I2) -> zagrevanje 15min@7:30; 6x(800m@6:05 +30sec@7:30); hlađenje 10min@7:30 | F16: =VLOOKUP(F3,Legenda!$A$1:$B$51,2,FALSE) -> 5k@6:00 ili odmor | G16: =SUBSTITUTE(SUBSTITUTE(SUBSTITUTE(SUBSTITUTE(SUBSTITUTE(SUBSTITUTE(SUBSTITUTE(SUBSTITUTE(G3,"1.5K",VO2max!B2),"3K",VO2max!C2),"5K",VO2max!D2),"10K",VO2max!E2),"21K",VO2max!F2),"42K",VO2max!G2),"ZA",VO2max!H2),"HL",VO2max!I2) -> zagrevanje 15min@7:30; 2x(3km@6:20+4min@7:30); hlađenje 10min@7:30 | H16: =VLOOKUP(H3,Legenda!$A$1:$B$51,2,FALSE) -> 14k@6:00
A17: 3 | B17: =VLOOKUP(B4,Legenda!$A$1:$B$51,2,FALSE) -> Plivanje, bicikla, šetanje, vežbe snage, ... | C17: =SUBSTITUTE(SUBSTITUTE(SUBSTITUTE(SUBSTITUTE(SUBSTITUTE(SUBSTITUTE(SUBSTITUTE(SUBSTITUTE(C4,"1.5K",VO2max!B2),"3K",VO2max!C2),"5K",VO2max!D2),"10K",VO2max!E2),"21k",VO2max!F2),"42K",VO2max!G2),"ZA",VO2max!H2),"HL",VO2max!I2) -> zagrevanje 15min@7:30; 3x(10min@6:20 +4min@7:30); hlađenje 10min@7:30 | D17: =VLOOKUP(D4,Legenda!$A$1:$B$51,2,FALSE) -> 5k@6:00 ili odmor | E17: =SUBSTITUTE(SUBSTITUTE(SUBSTITUTE(SUBSTITUTE(SUBSTITUTE(SUBSTITUTE(SUBSTITUTE(SUBSTITUTE(E4,"1.5K",VO2max!B2),"3K",VO2max!C2),"5K",VO2max!D2),"10K",VO2max!E2),"21k",VO2max!F2),"42K",VO2max!G2),"ZA",VO2max!H2),"HL",VO2max!I2) -> zagrevanje 15min@7:30; 2x(800m@6:20 + 600m@6:05 + 4min@7:30) hlađenje 10min@7:30 | F17: =VLOOKUP(F4,Legenda!$A$1:$B$51,2,FALSE) -> 5k@6:00 ili odmor | G17: =SUBSTITUTE(SUBSTITUTE(SUBSTITUTE(SUBSTITUTE(SUBSTITUTE(SUBSTITUTE(SUBSTITUTE(SUBSTITUTE(G4,"1.5K",VO2max!B2),"3K",VO2max!C2),"5K",VO2max!D2),"10K",VO2max!E2),"21K",VO2max!F2),"42K",VO2max!G2),"ZA",VO2max!H2),"HL",VO2max!I2) -> zagrevanje 15min@7:30; 1x40min@6:40; hlađenje 10min@7:30 | H17: =VLOOKUP(H4,Legenda!$A$1:$B$51,2,FALSE) -> 14k@6:00
A18: 4 | B18: =VLOOKUP(B5,Legenda!$A$1:$B$51,2,FALSE) -> 5k@6:00 ili odmor | C18: =SUBSTITUTE(SUBSTITUTE(SUBSTITUTE(SUBSTITUTE(SUBSTITUTE(SUBSTITUTE(SUBSTITUTE(SUBSTITUTE(C5,"1.5K",VO2max!B2),"3K",VO2max!C2),"5K",VO2max!D2),"10K",VO2max!E2),"21k",VO2max!F2),"42K",VO2max!G2),"ZA",VO2max!H2),"HL",VO2max!I2) -> zagrevanje 15min@7:30; 10x(200m@6:05 + 2min@7:30); hlađenje 10min@7:30 | D18: =VLOOKUP(D5,Legenda!$A$1:$B$51,2,FALSE) -> 5k@6:00 ili odmor | E18: =SUBSTITUTE(SUBSTITUTE(SUBSTITUTE(SUBSTITUTE(SUBSTITUTE(SUBSTITUTE(SUBSTITUTE(SUBSTITUTE(E5,"1.5K",VO2max!B2),"3K",VO2max!C2),"5K",VO2max!D2),"10K",VO2max!E2),"21k",VO2max!F2),"42K",VO2max!G2),"ZA",VO2max!H2),"HL",VO2max!I2) -> zagrevanje 15min@7:30; 12x(400m@6:05 +15sec@7:30); hlađenje 10min@7:30 | F18: =VLOOKUP(F5,Legenda!$A$1:$B$51,2,FALSE) -> 5k@6:00 ili odmor | G18: =SUBSTITUTE(SUBSTITUTE(SUBSTITUTE(SUBSTITUTE(SUBSTITUTE(SUBSTITUTE(SUBSTITUTE(SUBSTITUTE(G5,"1.5K",VO2max!B2),"3K",VO2max!C2),"5K",VO2max!D2),"10K",VO2max!E2),"21K",VO2max!F2),"42K",VO2max!G2),"ZA",VO2max!H2),"HL",VO2max!I2) -> zagrevanje 15min@7:30; 2x(400m@6:05 +800m@6:20+3200m@6:40 + 4min@7:30) hlađenje 10min@7:30 | H18: =VLOOKUP(H5,Legenda!$A$1:$B$51,2,FALSE) -> 14k@6:00
A19: 5 | B19: =VLOOKUP(B6,Legenda!$A$1:$B$51,2,FALSE) -> Plivanje, bicikla, šetanje, vežbe snage, ... | C19: =SUBSTITUTE(SUBSTITUTE(SUBSTITUTE(SUBSTITUTE(SUBSTITUTE(SUBSTITUTE(SUBSTITUTE(SUBSTITUTE(C6,"1.5K",VO2max!B2),"3K",VO2max!C2),"5K",VO2max!D2),"10K",VO2max!E2),"21k",VO2max!F2),"42K",VO2max!G2),"ZA",VO2max!H2),"HL",VO2max!I2) -> zagrevanje 15min@7:30; 4x(2km@6:20 +3min@7:30); hlađenje 10min@7:30 | D19: =VLOOKUP(D6,Legenda!$A$1:$B$51,2,FALSE) -> 5k@6:00 ili odmor | E19: =SUBSTITUTE(SUBSTITUTE(SUBSTITUTE(SUBSTITUTE(SUBSTITUTE(SUBSTITUTE(SUBSTITUTE(SUBSTITUTE(E6,"1.5K",VO2max!B2),"3K",VO2max!C2),"5K",VO2max!D2),"10K",VO2max!E2),"21k",VO2max!F2),"42K",VO2max!G2),"ZA",VO2max!H2),"HL",VO2max!I2) -> zagrevanje 15min@7:30; 2x(200m@5:40 + 400@6:00 + 4min@7:30) hlađenje 10min@7:30 | F19: =VLOOKUP(F6,Legenda!$A$1:$B$51,2,FALSE) -> 5k@6:00 ili odmor | G19: =SUBSTITUTE(SUBSTITUTE(SUBSTITUTE(SUBSTITUTE(SUBSTITUTE(SUBSTITUTE(SUBSTITUTE(SUBSTITUTE(G6,"1.5K",VO2max!B2),"3K",VO2max!C2),"5K",VO2max!D2),"10K",VO2max!E2),"21K",VO2max!F2),"42K",VO2max!G2),"ZA",VO2max!H2),"HL",VO2max!I2) -> zagrevanje 15min@7:30; 1x50min@6:40; hlađenje 10min@7:30 | H19: =VLOOKUP(H6,Legenda!$A$1:$B$51,2,FALSE) -> 14k@6:00
A20: 6 | B20: =VLOOKUP(B7,Legenda!$A$1:$B$51,2,FALSE) -> 5k@6:00 ili odmor | C20: =SUBSTITUTE(SUBSTITUTE(SUBSTITUTE(SUBSTITUTE(SUBSTITUTE(SUBSTITUTE(SUBSTITUTE(SUBSTITUTE(C7,"1.5K",VO2max!B2),"3K",VO2max!C2),"5K",VO2max!D2),"10K",VO2max!E2),"21k",VO2max!F2),"42K",VO2max!G2),"ZA",VO2max!H2),"HL",VO2max!I2) -> zagrevanje 15min@7:30; 10x(200m@6:00 + 1min@7:30); hlađenje 10min@7:30 | D20: =VLOOKUP(D7,Legenda!$A$1:$B$51,2,FALSE) -> progresivno aerobno trčanje u 3 jednaka segmenta, od sporijeg ka bržem | E20: =SUBSTITUTE(SUBSTITUTE(SUBSTITUTE(SUBSTITUTE(SUBSTITUTE(SUBSTITUTE(SUBSTITUTE(SUBSTITUTE(E7,"1.5K",VO2max!B2),"3K",VO2max!C2),"5K",VO2max!D2),"10K",VO2max!E2),"21k",VO2max!F2),"42K",VO2max!G2),"ZA",VO2max!H2),"HL",VO2max!I2) -> zagrevanje 15min@7:30; 4x(8min@6:20 +4min@7:30); hlađenje 10min@7:30 | F20: =VLOOKUP(F7,Legenda!$A$1:$B$51,2,FALSE) -> 5k@6:00 ili odmor | G20: =SUBSTITUTE(SUBSTITUTE(SUBSTITUTE(SUBSTITUTE(SUBSTITUTE(SUBSTITUTE(SUBSTITUTE(SUBSTITUTE(G7,"1.5K",VO2max!B2),"3K",VO2max!C2),"5K",VO2max!D2),"10K",VO2max!E2),"21K",VO2max!F2),"42K",VO2max!G2),"ZA",VO2max!H2),"HL",VO2max!I2) -> zagrevanje 15min@7:30; 3x(1600m@6:05 +1min@7:30); hlađenje 10min@7:30 | H20: =VLOOKUP(H7,Legenda!$A$1:$B$51,2,FALSE) -> 14k@6:00
A21: 7 | B21: =VLOOKUP(B8,Legenda!$A$1:$B$51,2,FALSE) -> Plivanje, bicikla, šetanje, vežbe snage, ... | C21: =SUBSTITUTE(SUBSTITUTE(SUBSTITUTE(SUBSTITUTE(SUBSTITUTE(SUBSTITUTE(SUBSTITUTE(SUBSTITUTE(C8,"1.5K",VO2max!B2),"3K",VO2max!C2),"5K",VO2max!D2),"10K",VO2max!E2),"21k",VO2max!F2),"42K",VO2max!G2),"ZA",VO2max!H2),"HL",VO2max!I2) -> zagrevanje 15min@7:30; 7x(1km@6:20 + 1min@7:30); hlađenje 10min@7:30 | D21: =VLOOKUP(D8,Legenda!$A$1:$B$51,2,FALSE) -> 5k@6:00 ili odmor | E21: =SUBSTITUTE(SUBSTITUTE(SUBSTITUTE(SUBSTITUTE(SUBSTITUTE(SUBSTITUTE(SUBSTITUTE(SUBSTITUTE(E8,"1.5K",VO2max!B2),"3K",VO2max!C2),"5K",VO2max!D2),"10K",VO2max!E2),"21k",VO2max!F2),"42K",VO2max!G2),"ZA",VO2max!H2),"HL",VO2max!I2) -> zagrevanje 15min@7:30; 8x(200m@6:00 +1min@7:30); hlađenje 10min@7:30 | F21: =VLOOKUP(F8,Legenda!$A$1:$B$51,2,FALSE) -> 5k@6:00 ili odmor | G21: =SUBSTITUTE(SUBSTITUTE(SUBSTITUTE(SUBSTITUTE(SUBSTITUTE(SUBSTITUTE(SUBSTITUTE(SUBSTITUTE(G8,"1.5K",VO2max!B2),"3K",VO2max!C2),"5K",VO2max!D2),"10K",VO2max!E2),"21K",VO2max!F2),"42K",VO2max!G2),"ZA",VO2max!H2),"HL",VO2max!I2) -> odmor | H21: =VLOOKUP(H8,Legenda!$A$1:$B$51,2,FALSE) -> zagrevanje 10min@ZA; 10k@10K; hlađenje 10min@HL
A22: 8 | B22: =VLOOKUP(B9,Legenda!$A$1:$B$51,2,FALSE) -> 5k@6:00 ili odmor | C22: =SUBSTITUTE(SUBSTITUTE(SUBSTITUTE(SUBSTITUTE(SUBSTITUTE(SUBSTITUTE(SUBSTITUTE(SUBSTITUTE(C9,"1.5K",VO2max!B2),"3K",VO2max!C2),"5K",VO2max!D2),"10K",VO2max!E2),"21k",VO2max!F2),"42K",VO2max!G2),"ZA",VO2max!H2),"HL",VO2max!I2) -> zagrevanje 15min@7:30; 8x(100m@6:00 + 2min@7:30); hlađenje 10min@7:30 | D22: =VLOOKUP(D9,Legenda!$A$1:$B$51,2,FALSE) -> 5k@6:00 ili odmor | E22: =SUBSTITUTE(SUBSTITUTE(SUBSTITUTE(SUBSTITUTE(SUBSTITUTE(SUBSTITUTE(SUBSTITUTE(SUBSTITUTE(E9,"1.5K",VO2max!B2),"3K",VO2max!C2),"5K",VO2max!D2),"10K",VO2max!E2),"21k",VO2max!F2),"42K",VO2max!G2),"ZA",VO2max!H2),"HL",VO2max!I2) -> zagrevanje 15min@7:30; 6x(800m@6:05 +30sec@7:30); hlađenje 10min@7:30 | F22: =VLOOKUP(F9,Legenda!$A$1:$B$51,2,FALSE) -> 5k@6:00 ili odmor | G22: =SUBSTITUTE(SUBSTITUTE(SUBSTITUTE(SUBSTITUTE(SUBSTITUTE(SUBSTITUTE(SUBSTITUTE(SUBSTITUTE(G9,"1.5K",VO2max!B2),"3K",VO2max!C2),"5K",VO2max!D2),"10K",VO2max!E2),"21K",VO2max!F2),"42K",VO2max!G2),"ZA",VO2max!H2),"HL",VO2max!I2) -> zagrevanje 15min@7:30; 3x(400m@6:05 +800m@6:20+3200m@6:40+4min@7:30); hlađenje 10min@7:30 | H22: =VLOOKUP(H9,Legenda!$A$1:$B$51,2,FALSE) -> 14k@6:00
A23: 9 | B23: =VLOOKUP(B10,Legenda!$A$1:$B$51,2,FALSE) -> Plivanje, bicikla, šetanje, vežbe snage, ... | C23: =SUBSTITUTE(SUBSTITUTE(SUBSTITUTE(SUBSTITUTE(SUBSTITUTE(SUBSTITUTE(SUBSTITUTE(SUBSTITUTE(C10,"1.5K",VO2max!B2),"3K",VO2max!C2),"5K",VO2max!D2),"10K",VO2max!E2),"21k",VO2max!F2),"42K",VO2max!G2),"ZA",VO2max!H2),"HL",VO2max!I2) -> zagrevanje 15min@7:30; 4x(2k@6:20 + 2min@7:30); hlađenje 10min@7:30 | D23: =VLOOKUP(D10,Legenda!$A$1:$B$51,2,FALSE) -> 5k@6:00 ili odmor | E23: =SUBSTITUTE(SUBSTITUTE(SUBSTITUTE(SUBSTITUTE(SUBSTITUTE(SUBSTITUTE(SUBSTITUTE(SUBSTITUTE(E10,"1.5K",VO2max!B2),"3K",VO2max!C2),"5K",VO2max!D2),"10K",VO2max!E2),"21k",VO2max!F2),"42K",VO2max!G2),"ZA",VO2max!H2),"HL",VO2max!I2) -> zagrevanje 15min@7:30; 5x(3min@6:00 + 3min@7:30); hlađenje 10min@7:30 | F23: =VLOOKUP(F10,Legenda!$A$1:$B$51,2,FALSE) -> 5k@6:00 ili odmor | G23: =SUBSTITUTE(SUBSTITUTE(SUBSTITUTE(SUBSTITUTE(SUBSTITUTE(SUBSTITUTE(SUBSTITUTE(SUBSTITUTE(G10,"1.5K",VO2max!B2),"3K",VO2max!C2),"5K",VO2max!D2),"10K",VO2max!E2),"21K",VO2max!F2),"42K",VO2max!G2),"ZA",VO2max!H2),"HL",VO2max!I2) -> zagrevanje 10min@7:30; 60min@6:40; hlađenje 10min@7:30 | H23: =VLOOKUP(H10,Legenda!$A$1:$B$51,2,FALSE) -> 14k@6:00
A24: 10 | B24: =VLOOKUP(B11,Legenda!$A$1:$B$51,2,FALSE) -> 5k@6:00, 4-6 x 100m ubrzanja na kraju treninga | C24: =SUBSTITUTE(SUBSTITUTE(SUBSTITUTE(SUBSTITUTE(SUBSTITUTE(SUBSTITUTE(SUBSTITUTE(SUBSTITUTE(C11,"1.5K",VO2max!B2),"3K",VO2max!C2),"5K",VO2max!D2),"10K",VO2max!E2),"21k",VO2max!F2),"42K",VO2max!G2),"ZA",VO2max!H2),"HL",VO2max!I2) -> zagrevanje 15min@7:30; 12x(200m@6:00 + 1min@7:30); hlađenje 10min@7:30 | D24: =VLOOKUP(D11,Legenda!$A$1:$B$51,2,FALSE) -> progresivno aerobno trčanje u 3 jednaka segmenta, od sporijeg ka bržem | E24: =SUBSTITUTE(SUBSTITUTE(SUBSTITUTE(SUBSTITUTE(SUBSTITUTE(SUBSTITUTE(SUBSTITUTE(SUBSTITUTE(E11,"1.5K",VO2max!B2),"3K",VO2max!C2),"5K",VO2max!D2),"10K",VO2max!E2),"21k",VO2max!F2),"42K",VO2max!G2),"ZA",VO2max!H2),"HL",VO2max!I2) -> zagrevanje 15min@7:30; 7x(1k@6:20 + 2min@7:30); hlađenje 10min@7:30 | F24: =VLOOKUP(F11,Legenda!$A$1:$B$51,2,FALSE) -> 5k@6:00 ili odmor | G24: =SUBSTITUTE(SUBSTITUTE(SUBSTITUTE(SUBSTITUTE(SUBSTITUTE(SUBSTITUTE(SUBSTITUTE(SUBSTITUTE(G11,"1.5K",VO2max!B2),"3K",VO2max!C2),"5K",VO2max!D2),"10K",VO2max!E2),"21K",VO2max!F2),"42K",VO2max!G2),"ZA",VO2max!H2),"HL",VO2max!I2) -> zagrevanje 10min@7:30; 30min@6:40; hlađenje 10min@7:30 | H24: =VLOOKUP(H11,Legenda!$A$1:$B$51,2,FALSE) -> 14k@6:00
A25: 11 | B25: =VLOOKUP(B12,Legenda!$A$1:$B$51,2,FALSE) -> 5k@6:00 ili odmor | C25: =SUBSTITUTE(SUBSTITUTE(SUBSTITUTE(SUBSTITUTE(SUBSTITUTE(SUBSTITUTE(SUBSTITUTE(SUBSTITUTE(C12,"1.5K",VO2max!B2),"3K",VO2max!C2),"5K",VO2max!D2),"10K",VO2max!E2),"21k",VO2max!F2),"42K",VO2max!G2),"ZA",VO2max!H2),"HL",VO2max!I2) -> zagrevanje 15min@7:30; 7x(1k@6:20 + 1min@7:30); hlađenje 10min@7:30 | D25: =VLOOKUP(D12,Legenda!$A$1:$B$51,2,FALSE) -> 5k@6:00 ili odmor | E25: =SUBSTITUTE(SUBSTITUTE(SUBSTITUTE(SUBSTITUTE(SUBSTITUTE(SUBSTITUTE(SUBSTITUTE(SUBSTITUTE(E12,"1.5K",VO2max!B2),"3K",VO2max!C2),"5K",VO2max!D2),"10K",VO2max!E2),"21k",VO2max!F2),"42K",VO2max!G2),"ZA",VO2max!H2),"HL",VO2max!I2) -> zagrevanje 15min@7:30; 5x(3min@6:00 + 3min@7:30); hlađenje 10min@7:30 | F25: =VLOOKUP(F12,Legenda!$A$1:$B$51,2,FALSE) -> 5k@6:00 ili odmor | G25: =SUBSTITUTE(SUBSTITUTE(SUBSTITUTE(SUBSTITUTE(SUBSTITUTE(SUBSTITUTE(SUBSTITUTE(SUBSTITUTE(G12,"1.5K",VO2max!B2),"3K",VO2max!C2),"5K",VO2max!D2),"10K",VO2max!E2),"21K",VO2max!F2),"42K",VO2max!G2),"ZA",VO2max!H2),"HL",VO2max!I2) -> odmor | H25: =VLOOKUP(H12,Legenda!$A$1:$B$51,2,FALSE) -> zagrevanje 10min@ZA; 5k@5K; hlađenje 10min@HL
A26: 12 | B26: =VLOOKUP(B13,Legenda!$A$1:$B$51,2,FALSE) -> 5k@6:00 ili odmor | C26: =SUBSTITUTE(SUBSTITUTE(SUBSTITUTE(SUBSTITUTE(SUBSTITUTE(SUBSTITUTE(SUBSTITUTE(SUBSTITUTE(C13,"1.5K",VO2max!B3),"3K",VO2max!C3),"5K",VO2max!D3),"10K",VO2max!E3),"21k",VO2max!F3),"42K",VO2max!G3),"ZA",VO2max!H3),"HL",VO2max!I3) -> zagrevanje 10min@; 20min@21K; hlađenje 10min@ | D26: =VLOOKUP(D13,Legenda!$A$1:$B$51,2,FALSE) -> Plivanje, bicikla, šetanje, vežbe snage, ... | E26: =SUBSTITUTE(SUBSTITUTE(SUBSTITUTE(SUBSTITUTE(SUBSTITUTE(SUBSTITUTE(SUBSTITUTE(SUBSTITUTE(E13,"1.5K",VO2max!B3),"3K",VO2max!C3),"5K",VO2max!D3),"10K",VO2max!E3),"21k",VO2max!F3),"42K",VO2max!G3),"ZA",VO2max!H3),"HL",VO2max!I3) -> zagrevanje 15min@; 3x(1.5min@ + 1.5min@); hlađenje 10min@ | F26: =VLOOKUP(F13,Legenda!$A$1:$B$51,2,FALSE) -> odmor | G26: =SUBSTITUTE(SUBSTITUTE(SUBSTITUTE(SUBSTITUTE(SUBSTITUTE(SUBSTITUTE(SUBSTITUTE(SUBSTITUTE(G13,"1.5K",VO2max!B3),"3K",VO2max!C3),"5K",VO2max!D3),"10K",VO2max!E3),"21K",VO2max!F3),"42K",VO2max!G3),"ZA",VO2max!H3),"HL",VO2max!I3) -> 3k@; 3x100m ubrzanja Ubrzanja se trče po ravnoj stazi i sa snagom od 85%. U pauzi se ili hoda ili lagano trči i ne počinje se ponovo dok se potpuno ne odmori. | H26: =VLOOKUP(H13,Legenda!$A$1:$B$51,2,FALSE) -> Obavezno uraditi zagrevanje laganim trčanjem na samom startu barem 1km Trka: 21.1km

Sheet 21kB-templ
A1: Nedelja | B1: DAN | C1: Trening | G1: Nedelja | H1: DAN | I1: Trening
A2: 1 | B2: Ponedeljak | C2: ='21kB'!B15 -> Plivanje, bicikla, šetanje, vežbe snage, ... | G2: 1 | H2: Ponedeljak | I2: Plivanje, bicikla, šetanje, vežbe snage, ...
B3: Utorak | C3: ='21kB'!C15 -> zagrevanje 15min@7:30; 2x(10min@6:20 +4min@7:30); hlađenje 10min@7:30 | H3: Utorak | I3: zagrevanje 15min@6:50; 2x(10min@5:35 +4min@6:50); hlađenje 10min@6:50
B4: Sreda | C4: ='21kB'!D15 -> 5k@6:00 ili odmor | H4: Sreda | I4: 5k@5:50 ili odmor
B5: Četvrtak | C5: ='21kB'!E15 -> zagrevanje 15min@7:30; 8x(400m@6:05 +1min@7:30); hlađenje 10min@7:30 | H5: Četvrtak | I5: zagrevanje 15min@6:50; 8x(400min@5:25 +1min@6:50); hlađenje 10min@6:50
B6: Petak | C6: ='21kB'!F15 -> 5k@6:00 ili odmor | H6: Petak | I6: 5k@5:50 ili odmor
B7: Subota | C7: ='21kB'!G15 -> zagrevanje 15min@7:30; 1x30min@6:40; hlađenje 10min@7:30 | H7: Subota | I7: zagrevanje 15min@6:50; 1x30min@5:55; hlađenje 10min@6:50
B8: Nedelja | C8: ='21kB'!H15 -> 14k@6:00 | H8: Nedelja | I8: 14k@5:50
A9: Nedelja | B9: DAN | C9: Trening | G9: Nedelja | H9: DAN | I9: Trening
A10: 2 | B10: Ponedeljak | C10: ='21kB'!B16 -> 5k@6:00 ili odmor | G10: 2 | H10: Ponedeljak | I10: 5k@5:50 ili odmor
B11: Utorak | C11: ='21kB'!C16 -> zagrevanje 15min@7:30; 16x(100m@6:00 + 1min@7:30); hlađenje 10min@7:30 | H11: Utorak | I11: zagrevanje 15min@6:50; 16x(100m@5:15 + 1min@6:50); hlađenje 10min@6:50
B12: Sreda | C12: ='21kB'!D16 -> 5k@6:00 ili odmor | H12: Sreda | I12: 5k@5:50 ili odmor
B13: Četvrtak | C13: ='21kB'!E16 -> zagrevanje 15min@7:30; 6x(800m@6:05 +30sec@7:30); hlađenje 10min@7:30 | H13: Četvrtak | I13: zagrevanje 15min@6:50; 6x(800min@5:25 +30sec@6:50); hlađenje 10min@6:50
B14: Petak | C14: ='21kB'!F16 -> 5k@6:00 ili odmor | H14: Petak | I14: 5k@5:50 ili odmor
B15: Subota | C15: ='21kB'!G16 -> zagrevanje 15min@7:30; 2x(3km@6:20+4min@7:30); hlađenje 10min@7:30 | H15: Subota | I15: zagrevanje 15min@6:50; 2x(3km@5:35+4min@6:50); hlađenje 10min@6:50
B16: Nedelja | C16: ='21kB'!H16 -> 14k@6:00 | H16: Nedelja | I16: 14k@5:50
A17: Nedelja | B17: DAN | C17: Trening | G17: Nedelja | H17: DAN | I17: Trening
A18: 3 | B18: Ponedeljak | C18: ='21kB'!B17 -> Plivanje, bicikla, šetanje, vežbe snage, ... | G18: 3 | H18: Ponedeljak | I18: Plivanje, bicikla, šetanje, vežbe snage, ...
B19: Utorak | C19: ='21kB'!C17 -> zagrevanje 15min@7:30; 3x(10min@6:20 +4min@7:30); hlađenje 10min@7:30 | H19: Utorak | I19: zagrevanje 15min@6:50; 3x(10min@5:35 +4min@6:50); hlađenje 10min@6:50
B20: Sreda | C20: ='21kB'!D17 -> 5k@6:00 ili odmor | H20: Sreda | I20: 5k@5:50 ili odmor
B21: Četvrtak | C21: ='21kB'!E17 -> zagrevanje 15min@7:30; 2x(800m@6:20 + 600m@6:05 + 4min@7:30) hlađenje 10min@7:30 | H21: Četvrtak | I21: zagrevanje 15min@6:50; 2x(800K@5:35 + 600m@5:25 + 4min@6:50) hlađenje 10min@6:50
B22: Petak | C22: ='21kB'!F17 -> 5k@6:00 ili odmor | H22: Petak | I22: 5k@5:50 ili odmor
B23: Subota | C23: ='21kB'!G17 -> zagrevanje 15min@7:30; 1x40min@6:40; hlađenje 10min@7:30 | H23: Subota | I23: zagrevanje 15min@6:50; 1x40min@5:55; hlađenje 10min@6:50
B24: Nedelja | C24: ='21kB'!H17 -> 14k@6:00 | H24: Nedelja | I24: 14k@5:50
A25: Nedelja | B25: DAN | C25: Trening | G25: Nedelja | H25: DAN | I25: Trening
A26: 4 | B26: Ponedeljak | C26: ='21kB'!B18 -> 5k@6:00 ili odmor | G26: 4 | H26: Ponedeljak | I26: 5k@5:50 ili odmor
B27: Utorak | C27: ='21kB'!C18 -> zagrevanje 15min@7:30; 10x(200m@6:05 + 2min@7:30); hlađenje 10min@7:30 | H27: Utorak | I27: zagrevanje 15min@5:50; 10x(200m@4:45 + 2min@5:50); hlađenje 10min@5:50
B28: Sreda | C28: ='21kB'!D18 -> 5k@6:00 ili odmor | H28: Sreda | I28: 5k@5:50 ili odmor
B29: Četvrtak | C29: ='21kB'!E18 -> zagrevanje 15min@7:30; 12x(400m@6:05 +15sec@7:30); hlađenje 10min@7:30 | H29: Četvrtak | I29: zagrevanje 15min@5:50; 12x(400m@4:45 +15sec@5:50); hlađenje 10min@5:50
B30: Petak | C30: ='21kB'!F18 -> 5k@6:00 ili odmor | H30: Petak | I30: 5k@5:50 ili odmor
B31: Subota | C31: ='21kB'!G18 -> zagrevanje 15min@7:30; 2x(400m@6:05 +800m@6:20+3200m@6:40 + 4min@7:30) hlađenje 10min@7:30 | H31: Subota | I31: zagrevanje 15min@5:50; 2x(400m@4:45 +800m@4:55+3200m@5:10 + 4min@5:50) hlađenje 10min@5:50
B32: Nedelja | C32: ='21kB'!H18 -> 14k@6:00 | H32: Nedelja | I32: 14k@5:50
A33: Nedelja | B33: DAN | C33: Trening | G33: Nedelja | H33: DAN | I33: Trening
A34: 5 | B34: Ponedeljak | C34: ='21kB'!B19 -> Plivanje, bicikla, šetanje, vežbe snage, ... | G34: 5 | H34: Ponedeljak | I34: Plivanje, bicikla, šetanje, vežbe snage, ...
B35: Utorak | C35: ='21kB'!C19 -> zagrevanje 15min@7:30; 4x(2km@6:20 +3min@7:30); hlađenje 10min@7:30 | H35: Utorak | I35: zagrevanje 15min@5:50; 4x(2km@4:55 +3min@5:50); hlađenje 10min@5:50
B36: Sreda | C36: ='21kB'!D19 -> 5k@6:00 ili odmor | H36: Sreda | I36: 5k@5:50 ili odmor
B37: Četvrtak | C37: ='21kB'!E19 -> zagrevanje 15min@7:30; 2x(200m@5:40 + 400@6:00 + 4min@7:30) hlađenje 10min@7:30 | H37: Četvrtak | I37: zagrevanje 15min@5:50; 2x(200m@4:20 + 400@4:35 + 4min@5:50) hlađenje 10min@5:50
B38: Petak | C38: ='21kB'!F19 -> 5k@6:00 ili odmor | H38: Petak | I38: 5k@5:50 ili odmor
B39: Subota | C39: ='21kB'!G19 -> zagrevanje 15min@7:30; 1x50min@6:40; hlađenje 10min@7:30 | H39: Subota | I39: zagrevanje 15min@5:50; 1x50min@5:10; hlađenje 10min@5:50
B40: Nedelja | C40: ='21kB'!H19 -> 14k@6:00 | H40: Nedelja | I40: 14k@5:50
...

Sheet 42kB
A1: Nedelja | B1: PO | C1: UT | D1: SR | E1: CE | F1: PE | G1: SU | H1: NE
A2: 1 | B2: XT | C2: zagrevanje 15min@ZA; 3x(8min@10K + 3min@ZA); hlađenje 10min@HL | D2: A | E2: zagrevanje 15min@ZA; 6x(800min@5K + 30s@ZA); hlađenje 10min@HL | F2: E | G2: E1 | H2: L1
A3: 2 | B3: E | C3: zagrevanje 15min@ZA; 14x(200m@3K + 1min@ZA); hlađenje 10min@HL | D3: A1 | E3: zagrevanje 15min@ZA; 2x(3k@10K +4min@ZA); hlađenje 10min@HL | F3: E | G3: A1 | H3: L
A4: 3 | B4: XT | C4: zagrevanje 15min@ZA; 2x(200K@3K + 600m@5K + 1600m@10K + 4min@ZA) hlađenje 10min@HL | D4: E | E4: zagrevanje 15min@ZA; 5x(1000m@5K + 1min@ZA) hlađenje 10min@HL | F4: E | G4: A1 | H4: zagrevanje 10min@ZA; 60min@42K; hlađenje 10min@HL
A5: 4 | B5: E | C5: zagrevanje 15min@ZA; 3x(8min@10K + 2min@ZA); hlađenje 10min@HL | D5: E | E5: zagrevanje 15min@ZA; 3x(1600m@5K +1min@ZA); hlađenje 10min@HL | F5: E | G5: zagrevanje 15min@ZA; 20min@21K hlađenje 10min@HL | H5: L
A6: 5 | B6: XT | C6: zagrevanje 15min@ZA; 5x(3min@3K +3min@ZA); hlađenje 10min@HL | D6: A | E6: zagrevanje 15min@ZA; 7x(1000m@10K + 1min@ZA) hlađenje 10min@HL | F6: E | G6: odmor | H6: zagrevanje 10min@ZA; 90min@42K; hlađenje 10min@HL
A7: 6 | B7: E | C7: zagrevanje 15min@ZA; 1k@10K + 2min@ZA+3k@10K + 5min@ZA + 1k@10K + 2min@ZA+ 3k@10K + 5min@ZA + 1k@10K hlađenje 10min@HL | D7: A1 | E7: zagrevanje 15min@ZA; 4x(8min@10K +4min@ZA); hlađenje 10min@HL | F7: E | G7: zagrevanje 15min@ZA; 30min@21K hlađenje 10min@HL | H7: L1
A8: 7 | B8: odmor | C8: zagrevanje 15min@ZA; 8x(400m@10K + 30sec@ZA); hlađenje 10min@HL | D8: A | E8: zagrevanje 15min@ZA; 8x(200m@3K +1min@ZA); hlađenje 10min@HL | F8: E | G8: odmor | H8: zagrevanje 10min@ZA; 21k@21K; hlađenje 5min@HL
A9: 8 | B9: E | C9: zagrevanje 15min@ZA; 2x(400m@5K + 400m@10K + 2400m@42K + 4min@ZA); hlađenje 10min@HL | D9: A | E9: zagrevanje 15min@ZA; 6x(800m@5K +30sec@ZA); hlađenje 10min@HL | F9: A | G9: E | H9: L2
A10: 9 | B10: E1 | C10: zagrevanje 15min@ZA; 4x(2k@10K + 2min@ZA); hlađenje 10min@HL | D10: A | E10: zagrevanje 15min@ZA; 5x(3min@3K + 3min@ZA); hlađenje 10min@HL | F10: E | G10: zagrevanje 10min@ZA; 2x(20min@21K + 5min@ZA); hlađenje 10min@HL | H10: L
A11: 10 | B11: XT | C11: zagrevanje 15min@ZA; 14x(200m@3K + 1min@ZA); hlađenje 10min@HL | D11: A1 | E11: zagrevanje 15min@ZA; 3x(400m@5K + 400m@10K + 2400m@42K + 4min@ZA); hlađenje 10min@HL | F11: E | G11: zagrevanje 10min@ZA; 40min@21K; hlađenje 10min@HL | H11: zagrevanje 10min@ZA; 120min@42K; hlađenje 10min@HL
A12: 11 | B12: E | C12: zagrevanje 15min@ZA; 3x(1600m@5K + 1min@ZA); hlađenje 10min@HL | D12: A | E12: zagrevanje 15min@ZA; 5x(3min@3K + 3min@ZA); hlađenje 10min@HL | F12: E | G12: odmor | H12: zagrevanje 10min@ZA; 5k@5K; hlađenje 10min@HL
A13: 12 | B13: odmor | C13: zagrevanje 10min@ZA; 20min@21K; hlađenje 10min@HL | D13: XT | E13: zagrevanje 15min@ZA; 3x(1.5min@5K + 1.5min@ZA); hlađenje 10min@HL | F13: odmor | G13: 3k@ZA; 3x100m ubrzanja Ubrzanja se trče po ravnoj stazi i sa snagom od 85%. U pauzi se ili hoda ili lagano trči i ne počinje se ponovo dok se potpuno ne odmori. | H13: Obavezno uraditi zagrevanje laganim trčanjem na samom startu barem 1km Trka: 42.2km
A14: Nedelja | B14: PO | C14: UT | D14: SR | E14: CE | F14: PE | G14: SU | H14: NE
A15: 1 | B15: =VLOOKUP(B2,Legenda!$A$1:$B$51,2,FALSE) -> Plivanje, bicikla, šetanje, vežbe snage, ... | C15: =SUBSTITUTE(SUBSTITUTE(SUBSTITUTE(SUBSTITUTE(SUBSTITUTE(SUBSTITUTE(SUBSTITUTE(SUBSTITUTE(C2,"1.5K",VO2max!B2),"3K",VO2max!C2),"5K",VO2max!D2),"10K",VO2max!E2),"21k",VO2max!F2),"42K",VO2max!G2),"ZA",VO2max!H2),"HL",VO2max!I2) -> zagrevanje 15min@7:30; 3x(8min@6:20 + 3min@7:30); hlađenje 10min@7:30 | D15: =VLOOKUP(D2,Legenda!$A$1:$B$51,2,FALSE) -> 5k@6:00 ili odmor | E15: =SUBSTITUTE(SUBSTITUTE(SUBSTITUTE(SUBSTITUTE(SUBSTITUTE(SUBSTITUTE(SUBSTITUTE(SUBSTITUTE(E2,"1.5K",VO2max!B2),"3K",VO2max!C2),"5K",VO2max!D2),"10K",VO2max!E2),"21k",VO2max!F2),"42K",VO2max!G2),"ZA",VO2max!H2),"HL",VO2max!I2) -> zagrevanje 15min@7:30; 6x(800min@6:05 + 30s@7:30); hlađenje 10min@7:30 | F15: =VLOOKUP(F2,Legenda!$A$1:$B$51,2,FALSE) -> 5k@6:00 ili odmor | G15: =VLOOKUP(G2,Legenda!$A$1:$B$51,2,FALSE) -> 5k@6:00, 4-6 x 100m ubrzanja na kraju treninga | H15: =VLOOKUP(H2,Legenda!$A$1:$B$51,2,FALSE) -> 14k@6:00
A16: 2 | B16: =VLOOKUP(B3,Legenda!$A$1:$B$51,2,FALSE) -> 5k@6:00 ili odmor | C16: =SUBSTITUTE(SUBSTITUTE(SUBSTITUTE(SUBSTITUTE(SUBSTITUTE(SUBSTITUTE(SUBSTITUTE(SUBSTITUTE(C3,"1.5K",VO2max!B2),"3K",VO2max!C2),"5K",VO2max!D2),"10K",VO2max!E2),"21k",VO2max!F2),"42K",VO2max!G2),"ZA",VO2max!H2),"HL",VO2max!I2) -> zagrevanje 15min@7:30; 14x(200m@6:00 + 1min@7:30); hlađenje 10min@7:30 | D16: =VLOOKUP(D3,Legenda!$A$1:$B$51,2,FALSE) -> progresivno aerobno trčanje u 3 jednaka segmenta, od sporijeg ka bržem | E16: =SUBSTITUTE(SUBSTITUTE(SUBSTITUTE(SUBSTITUTE(SUBSTITUTE(SUBSTITUTE(SUBSTITUTE(SUBSTITUTE(E3,"1.5K",VO2max!B2),"3K",VO2max!C2),"5K",VO2max!D2),"10K",VO2max!E2),"21k",VO2max!F2),"42K",VO2max!G2),"ZA",VO2max!H2),"HL",VO2max!I2) -> zagrevanje 15min@7:30; 2x(3k@6:20 +4min@7:30); hlađenje 10min@7:30 | F16: =VLOOKUP(F3,Legenda!$A$1:$B$51,2,FALSE) -> 5k@6:00 ili odmor | G16: =VLOOKUP(G3,Legenda!$A$1:$B$51,2,FALSE) -> progresivno aerobno trčanje u 3 jednaka segmenta, od sporijeg ka bržem | H16: =VLOOKUP(H3,Legenda!$A$1:$B$51,2,FALSE) -> 14k@6:00
A17: 3 | B17: =VLOOKUP(B4,Legenda!$A$1:$B$51,2,FALSE) -> Plivanje, bicikla, šetanje, vežbe snage, ... | C17: =SUBSTITUTE(SUBSTITUTE(SUBSTITUTE(SUBSTITUTE(SUBSTITUTE(SUBSTITUTE(SUBSTITUTE(SUBSTITUTE(C4,"1.5K",VO2max!B2),"3K",VO2max!C2),"5K",VO2max!D2),"10K",VO2max!E2),"21k",VO2max!F2),"42K",VO2max!G2),"ZA",VO2max!H2),"HL",VO2max!I2) -> zagrevanje 15min@7:30; 2x(200K@6:00 + 600m@6:05 + 1600m@6:20 + 4min@7:30) hlađenje 10min@7:30 | D17: =VLOOKUP(D4,Legenda!$A$1:$B$51,2,FALSE) -> 5k@6:00 ili odmor | E17: =SUBSTITUTE(SUBSTITUTE(SUBSTITUTE(SUBSTITUTE(SUBSTITUTE(SUBSTITUTE(SUBSTITUTE(SUBSTITUTE(E4,"1.5K",VO2max!B2),"3K",VO2max!C2),"5K",VO2max!D2),"10K",VO2max!E2),"21k",VO2max!F2),"42K",VO2max!G2),"ZA",VO2max!H2),"HL",VO2max!I2) -> zagrevanje 15min@7:30; 5x(1000m@6:05 + 1min@7:30) hlađenje 10min@7:30 | F17: =VLOOKUP(F4,Legenda!$A$1:$B$51,2,FALSE) -> 5k@6:00 ili odmor | G17: =VLOOKUP(G4,Legenda!$A$1:$B$51,2,FALSE) -> progresivno aerobno trčanje u 3 jednaka segmenta, od sporijeg ka bržem | H17: =H4 -> zagrevanje 10min@ZA; 60min@42K; hlađenje 10min@HL
A18: 4 | B18: =VLOOKUP(B5,Legenda!$A$1:$B$51,2,FALSE) -> 5k@6:00 ili odmor | C18: =SUBSTITUTE(SUBSTITUTE(SUBSTITUTE(SUBSTITUTE(SUBSTITUTE(SUBSTITUTE(SUBSTITUTE(SUBSTITUTE(C5,"1.5K",VO2max!B2),"3K",VO2max!C2),"5K",VO2max!D2),"10K",VO2max!E2),"21k",VO2max!F2),"42K",VO2max!G2),"ZA",VO2max!H2),"HL",VO2max!I2) -> zagrevanje 15min@7:30; 3x(8min@6:20 + 2min@7:30); hlađenje 10min@7:30 | D18: =VLOOKUP(D5,Legenda!$A$1:$B$51,2,FALSE) -> 5k@6:00 ili odmor | E18: =SUBSTITUTE(SUBSTITUTE(SUBSTITUTE(SUBSTITUTE(SUBSTITUTE(SUBSTITUTE(SUBSTITUTE(SUBSTITUTE(E5,"1.5K",VO2max!B2),"3K",VO2max!C2),"5K",VO2max!D2),"10K",VO2max!E2),"21k",VO2max!F2),"42K",VO2max!G2),"ZA",VO2max!H2),"HL",VO2max!I2) -> zagrevanje 15min@7:30; 3x(1600m@6:05 +1min@7:30); hlađenje 10min@7:30 | F18: =VLOOKUP(F5,Legenda!$A$1:$B$51,2,FALSE) -> 5k@6:00 ili odmor | G18: =SUBSTITUTE(SUBSTITUTE(SUBSTITUTE(SUBSTITUTE(SUBSTITUTE(SUBSTITUTE(SUBSTITUTE(SUBSTITUTE(G5,"1.5K",VO2max!B2),"3K",VO2max!C2),"5K",VO2max!D2),"10K",VO2max!E2),"21K",VO2max!F2),"42K",VO2max!G2),"ZA",VO2max!H2),"HL",VO2max!I2) -> zagrevanje 15min@7:30; 20min@6:40 hlađenje 10min@7:30 | H18: =VLOOKUP(H5,Legenda!$A$1:$B$51,2,FALSE) -> 14k@6:00
A19: 5 | B19: =VLOOKUP(B6,Legenda!$A$1:$B$51,2,FALSE) -> Plivanje, bicikla, šetanje, vežbe snage, ... | C19: =SUBSTITUTE(SUBSTITUTE(SUBSTITUTE(SUBSTITUTE(SUBSTITUTE(SUBSTITUTE(SUBSTITUTE(SUBSTITUTE(C6,"1.5K",VO2max!B2),"3K",VO2max!C2),"5K",VO2max!D2),"10K",VO2max!E2),"21k",VO2max!F2),"42K",VO2max!G2),"ZA",VO2max!H2),"HL",VO2max!I2) -> zagrevanje 15min@7:30; 5x(3min@6:00 +3min@7:30); hlađenje 10min@7:30 | D19: =VLOOKUP(D6,Legenda!$A$1:$B$51,2,FALSE) -> 5k@6:00 ili odmor | E19: =SUBSTITUTE(SUBSTITUTE(SUBSTITUTE(SUBSTITUTE(SUBSTITUTE(SUBSTITUTE(SUBSTITUTE(SUBSTITUTE(E6,"1.5K",VO2max!B2),"3K",VO2max!C2),"5K",VO2max!D2),"10K",VO2max!E2),"21k",VO2max!F2),"42K",VO2max!G2),"ZA",VO2max!H2),"HL",VO2max!I2) -> zagrevanje 15min@7:30; 7x(1000m@6:20 + 1min@7:30) hlađenje 10min@7:30 | F19: =VLOOKUP(F6,Legenda!$A$1:$B$51,2,FALSE) -> 5k@6:00 ili odmor | G19: =SUBSTITUTE(SUBSTITUTE(SUBSTITUTE(SUBSTITUTE(SUBSTITUTE(SUBSTITUTE(SUBSTITUTE(SUBSTITUTE(G6,"1.5K",VO2max!B2),"3K",VO2max!C2),"5K",VO2max!D2),"10K",VO2max!E2),"21K",VO2max!F2),"42K",VO2max!G2),"ZA",VO2max!H2),"HL",VO2max!I2) -> odmor | H19: =H6 -> zagrevanje 10min@ZA; 90min@42K; hlađenje 10min@HL
A20: 6 | B20: =VLOOKUP(B7,Legenda!$A$1:$B$51,2,FALSE) -> 5k@6:00 ili odmor | C20: =SUBSTITUTE(SUBSTITUTE(SUBSTITUTE(SUBSTITUTE(SUBSTITUTE(SUBSTITUTE(SUBSTITUTE(SUBSTITUTE(C7,"1.5K",VO2max!B2),"3K",VO2max!C2),"5K",VO2max!D2),"10K",VO2max!E2),"21k",VO2max!F2),"42K",VO2max!G2),"ZA",VO2max!H2),"HL",VO2max!I2) -> zagrevanje 15min@7:30; 1k@6:20 + 2min@7:30+3k@6:20 + 5min@7:30 + 1k@6:20 + 2min@7:30+ 3k@6:20 + 5min@7:30 + 1k@6:20 hlađenje 10min@7:30 | D20: =VLOOKUP(D7,Legenda!$A$1:$B$51,2,FALSE) -> progresivno aerobno trčanje u 3 jednaka segmenta, od sporijeg ka bržem | E20: =SUBSTITUTE(SUBSTITUTE(SUBSTITUTE(SUBSTITUTE(SUBSTITUTE(SUBSTITUTE(SUBSTITUTE(SUBSTITUTE(E7,"1.5K",VO2max!B2),"3K",VO2max!C2),"5K",VO2max!D2),"10K",VO2max!E2),"21k",VO2max!F2),"42K",VO2max!G2),"ZA",VO2max!H2),"HL",VO2max!I2) -> zagrevanje 15min@7:30; 4x(8min@6:20 +4min@7:30); hlađenje 10min@7:30 | F20: =VLOOKUP(F7,Legenda!$A$1:$B$51,2,FALSE) -> 5k@6:00 ili odmor | G20: =SUBSTITUTE(SUBSTITUTE(SUBSTITUTE(SUBSTITUTE(SUBSTITUTE(SUBSTITUTE(SUBSTITUTE(SUBSTITUTE(G7,"1.5K",VO2max!B2),"3K",VO2max!C2),"5K",VO2max!D2),"10K",VO2max!E2),"21K",VO2max!F2),"42K",VO2max!G2),"ZA",VO2max!H2),"HL",VO2max!I2) -> zagrevanje 15min@7:30; 30min@6:40 hlađenje 10min@7:30 | H20: =VLOOKUP(H7,Legenda!$A$1:$B$51,2,FALSE) -> 14k@6:00
A21: 7 | B21: =VLOOKUP(B8,Legenda!$A$1:$B$51,2,FALSE) -> odmor | C21: =SUBSTITUTE(SUBSTITUTE(SUBSTITUTE(SUBSTITUTE(SUBSTITUTE(SUBSTITUTE(SUBSTITUTE(SUBSTITUTE(C8,"1.5K",VO2max!B2),"3K",VO2max!C2),"5K",VO2max!D2),"10K",VO2max!E2),"21k",VO2max!F2),"42K",VO2max!G2),"ZA",VO2max!H2),"HL",VO2max!I2) -> zagrevanje 15min@7:30; 8x(400m@6:20 + 30sec@7:30); hlađenje 10min@7:30 | D21: =VLOOKUP(D8,Legenda!$A$1:$B$51,2,FALSE) -> 5k@6:00 ili odmor | E21: =SUBSTITUTE(SUBSTITUTE(SUBSTITUTE(SUBSTITUTE(SUBSTITUTE(SUBSTITUTE(SUBSTITUTE(SUBSTITUTE(E8,"1.5K",VO2max!B2),"3K",VO2max!C2),"5K",VO2max!D2),"10K",VO2max!E2),"21k",VO2max!F2),"42K",VO2max!G2),"ZA",VO2max!H2),"HL",VO2max!I2) -> zagrevanje 15min@7:30; 8x(200m@6:00 +1min@7:30); hlađenje 10min@7:30 | F21: =VLOOKUP(F8,Legenda!$A$1:$B$51,2,FALSE) -> 5k@6:00 ili odmor | G21: =SUBSTITUTE(SUBSTITUTE(SUBSTITUTE(SUBSTITUTE(SUBSTITUTE(SUBSTITUTE(SUBSTITUTE(SUBSTITUTE(G8,"1.5K",VO2max!B2),"3K",VO2max!C2),"5K",VO2max!D2),"10K",VO2max!E2),"21K",VO2max!F2),"42K",VO2max!G2),"ZA",VO2max!H2),"HL",VO2max!I2) -> odmor | H21: =H8 -> zagrevanje 10min@ZA; 21k@21K; hlađenje 5min@HL
